Workbook

Sheet ZMRP
A1: Application | B1: Condition Type | C1: Material | D1: Valid to | E1: Valid From | F1: Amount | G1: Unit of measure | H1: ok
A2: V | B2: ZMRP | C2: 1403173 | D2: 2958465 | E2: 44764 | F2: 175 | G2: CAN
A3: V | B3: ZMRP | C3: 1403174 | D3: 2958465 | E3: 44764 | F3: 175 | G3: CAN
A4: V | B4: ZMRP | C4: 1403176 | D4: 2958465 | E4: 44764 | F4: 175 | G4: CAN
A5: V | B5: ZMRP | C5: 1403177 | D5: 2958465 | E5: 44764 | F5: 175 | G5: CAN
A6: V | B6: ZMRP | C6: 1403183 | D6: 2958465 | E6: 44764 | F6: 335 | G6: CAN
A7: V | B7: ZMRP | C7: 1403184 | D7: 2958465 | E7: 44764 | F7: 335 | G7: CAN
A8: V | B8: ZMRP | C8: 1403187 | D8: 2958465 | E8: 44764 | F8: 335 | G8: CAN
A9: V | B9: ZMRP | C9: 1403188 | D9: 2958465 | E9: 44764 | F9: 335 | G9: CAN
A10: V | B10: ZMRP | C10: 1403229 | D10: 2958465 | E10: 44764 | F10: 335 | G10: CAN
A11: V | B11: ZMRP | C11: 1403233 | D11: 2958465 | E11: 44764 | F11: 1650 | G11: CAN
A12: V | B12: ZMRP | C12: 1403234 | D12: 2958465 | E12: 44764 | F12: 1650 | G12: CAN
A13: V | B13: ZMRP | C13: 1403240 | D13: 2958465 | E13: 44764 | F13: 1650 | G13: CAN
... A3564: V | B3564: ZMRP | C3564: 9901906 | D3564: 2958465 | E3564: 44431 | F3564: 105 | G3564: CAN

Sheet ZLAM
A1: Application | B1: Condition Type | C1: Material | D1: Valid to | E1: Valid From | F1: Amount | G1: Unit of measure | H1: oka
A2: V | B2: ZLAM | C2: 1304233 | D2: 2958465 | E2: 42300 | F2: 83.33
A3: V | B3: ZLAM | C3: 1403173 | D3: 2958465 | E3: 44764 | F3: 80.85
A4: V | B4: ZLAM | C4: 1403174 | D4: 2958465 | E4: 44764 | F4: 80.85
A5: V | B5: ZLAM | C5: 1403176 | D5: 2958465 | E5: 44764 | F5: 80.85
A6: V | B6: ZLAM | C6: 1403177 | D6: 2958465 | E6: 44764 | F6: 80.85
A7: V | B7: ZLAM | C7: 1403183 | D7: 2958465 | E7: 44764 | F7: 82.23
A8: V | B8: ZLAM | C8: 1403184 | D8: 2958465 | E8: 44764 | F8: 82.23
A9: V | B9: ZLAM | C9: 1403187 | D9: 2958465 | E9: 44764 | F9: 82.23
A10: V | B10: ZLAM | C10: 1403188 | D10: 2958465 | E10: 44764 | F10: 82.23
A11: V | B11: ZLAM | C11: 1403229 | D11: 2958465 | E11: 44764 | F11: 82.23
A12: V | B12: ZLAM | C12: 1403233 | D12: 2958465 | E12: 44764 | F12: 82.32
A13: V | B13: ZLAM | C13: 1403234 | D13: 2958465 | E13: 44764 | F13: 82.32
... A3596: V | B3596: ZLAM | C3596: 9901906 | D3596: 2958465 | E3596: 44431 | F3596: 80

Sheet ZTRV
A1: Application | B1: Condition Type | C1: Customer group | D1: Material | E1: Valid to | F1: Valid From | G1: Amount | H1: Unit of measure | I1: oka
A2: V | B2: ZTRV | C2: SA | D2: 1301288 | E2: 46022 | F2: 45931 | G2: -8 | H2: L29
A3: V | B3: ZTRV | C3: SA | D3: 1301401 | E3: 46022 | F3: 45931 | G3: -8 | H3: L29
A4: V | B4: ZTRV | C4: SA | D4: 1303401 | E4: 46022 | F4: 45931 | G4: -8 | H4: L29
A5: V | B5: ZTRV | C5: SA | D5: 1304401 | E5: 46022 | F5: 45931 | G5: -8 | H5: L29
A6: V | B6: ZTRV | C6: SA | D6: 1305401 | E6: 46022 | F6: 45931 | G6: -8 | H6: L29
A7: V | B7: ZTRV | C7: SA | D7: 1403401 | E7: 46022 | F7: 45931 | G7: -8 | H7: L29
A8: V | B8: ZTRV | C8: SA | D8: 1404183 | E8: 46022 | F8: 45931 | G8: -8 | H8: L29
A9: V | B9: ZTRV | C9: SA | D9: 1404184 | E9: 46022 | F9: 45931 | G9: -8 | H9: L29
A10: V | B10: ZTRV | C10: SA | D10: 1404233 | E10: 46022 | F10: 45931 | G10: -8 | H10: L29
A11: V | B11: ZTRV | C11: SA | D11: 1404234 | E11: 46022 | F11: 45931 | G11: -8 | H11: L29
A12: V | B12: ZTRV | C12: SA | D12: 1404242 | E12: 46022 | F12: 45931 | G12: -8 | H12: L29
A13: V | B13: ZTRV | C13: SA | D13: 1404265 | E13: 46022 | F13: 45931 | G13: -8 | H13: L29
... A676: V | B676: ZTRV | C676: SA | D676: 7903451 | E676: 46022 | F676: 45931 | G676: -23 | H676: KG

Sheet ZTR1
A1: Application | B1: Condition Type | C1: Customer group | D1: Material | E1: Valid to | F1: Valid From | G1: Amount | H1: Unit of measure | I1: oka
A2: V | B2: ZTR1 | C2: SA | D2: 2825022 | E2: 45961 | F2: 45937 | G2: -200 | H2: L29
A3: V | B3: ZTR1 | C3: SA | D3: 2825023 | E3: 45961 | F3: 45937 | G3: -200 | H3: L29
A4: V | B4: ZTR1 | C4: SA | D4: 2825181 | E4: 45961 | F4: 45937 | G4: -200 | H4: L29
A5: V | B5: ZTR1 | C5: SA | D5: 2825183 | E5: 45961 | F5: 45937 | G5: -200 | H5: L29
A6: V | B6: ZTR1 | C6: SA | D6: 2825185 | E6: 45961 | F6: 45937 | G6: -200 | H6: L29
A7: V | B7: ZTR1 | C7: SA | D7: 2825258 | E7: 45961 | F7: 45937 | G7: -200 | H7: L29

Sheet ZTR2
A1: Application | B1: Condition Type | C1: Customer group | D1: Material | E1: Valid to | F1: Valid From | G1: Amount | H1: Unit of measure | I1: oka

Sheet ZSSD
A1: Application | B1: Condition Type | C1: Customer group | D1: Material | E1: Valid to | F1: Valid From | G1: Amount | H1: Unit of measure | J1: oka | K1: Mate | L1: rial
A2: V | B2: ZSSD | C2: SA | D2: 1408163 | E2: 46112 | F2: 45748 | G2: -4 | H2: L29 | I2: =VLOOKUP(K2,[1]GRADE!$A:$P,16,FALSE) -> SILVER | K2: 1408 | L2: 163
A3: V | B3: ZSSD | C3: SA | D3: 1408164 | E3: 46112 | F3: 45748 | G3: -4 | H3: L29 | I3: =VLOOKUP(K3,[1]GRADE!$A:$P,16,FALSE) -> SILVER | K3: 1408 | L3: 164
A4: V | B4: ZSSD | C4: SA | D4: 1408183 | E4: 46112 | F4: 45748 | G4: -4 | H4: L29 | I4: =VLOOKUP(K4,[1]GRADE!$A:$P,16,FALSE) -> SILVER | K4: 1408 | L4: 183
A5: V | B5: ZSSD | C5: SA | D5: 1408184 | E5: 46112 | F5: 45748 | G5: -4 | H5: L29 | I5: =VLOOKUP(K5,[1]GRADE!$A:$P,16,FALSE) -> SILVER | K5: 1408 | L5: 184
A6: V | B6: ZSSD | C6: SA | D6: 1408243 | E6: 46112 | F6: 45748 | G6: -4 | H6: L29 | I6: =VLOOKUP(K6,[1]GRADE!$A:$P,16,FALSE) -> SILVER | K6: 1408 | L6: 243
A7: V | B7: ZSSD | C7: SA | D7: 1408244 | E7: 46112 | F7: 45748 | G7: -4 | H7: L29 | I7: =VLOOKUP(K7,[1]GRADE!$A:$P,16,FALSE) -> SILVER | K7: 1408 | L7: 244
A8: V | B8: ZSSD | C8: SA | D8: 1412183 | E8: 46112 | F8: 45748 | G8: -4 | H8: L29 | I8: =VLOOKUP(K8,[1]GRADE!$A:$P,16,FALSE) -> SILVER | K8: 1412 | L8: 183
A9: V | B9: ZSSD | C9: SA | D9: 1412184 | E9: 46112 | F9: 45748 | G9: -4 | H9: L29 | I9: =VLOOKUP(K9,[1]GRADE!$A:$P,16,FALSE) -> SILVER | K9: 1412 | L9: 184
A10: V | B10: ZSSD | C10: SA | D10: 1412196 | E10: 46112 | F10: 45748 | G10: -4 | H10: L29 | I10: =VLOOKUP(K10,[1]GRADE!$A:$P,16,FALSE) -> SILVER | K10: 1412 | L10: 196
A11: V | B11: ZSSD | C11: SA | D11: 1412197 | E11: 46112 | F11: 45748 | G11: -4 | H11: L29 | I11: =VLOOKUP(K11,[1]GRADE!$A:$P,16,FALSE) -> SILVER | K11: 1412 | L11: 197
A12: V | B12: ZSSD | C12: SA | D12: 1412233 | E12: 46112 | F12: 45748 | G12: -4 | H12: L29 | I12: =VLOOKUP(K12,[1]GRADE!$A:$P,16,FALSE) -> SILVER | K12: 1412 | L12: 233
A13: V | B13: ZSSD | C13: SA | D13: 1412234 | E13: 46112 | F13: 45748 | G13: -4 | H13: L29 | I13: =VLOOKUP(K13,[1]GRADE!$A:$P,16,FALSE) -> SILVER | K13: 1412 | L13: 234
... A30: V | B30: ZSSD | C30: SA | D30: 1415295 | E30: 46112 | F30: 45748 | G30: -4 | H30: L29 | I30: =VLOOKUP(K30,[1]GRADE!$A:$P,16,FALSE) -> SILVER | K30: 1415 | L30: 295
A31: V | B31: ZSSD | C31: SA | D31: 2050180 | E31: 46112 | F31: 45748 | G31: -8 | I31: =VLOOKUP(K31,[1]GRADE!$A:$P,16,FALSE) -> Gold | K31: 2050 | L31: 180
A32: V | B32: ZSSD | C32: SA | D32: 2050221 | E32: 46112 | F32: 45748 | G32: -8 | I32: =VLOOKUP(K32,[1]GRADE!$A:$P,16,FALSE) -> Gold | K32: 2050 | L32: 221
A33: V | B33: ZSSD | C33: SA | D33: 2050223 | E33: 46112 | F33: 45748 | G33: -8 | I33: =VLOOKUP(K33,[1]GRADE!$A:$P,16,FALSE) -> Gold | K33: 2050 | L33: 223
A34: V | B34: ZSSD | C34: SA | D34: 2051180 | E34: 46112 | F34: 45748 | G34: -8 | I34: =VLOOKUP(K34,[1]GRADE!$A:$P,16,FALSE) -> Gold | K34: 2051 | L34: 180
A35: V | B35: ZSSD | C35: SA | D35: 2051221 | E35: 46112 | F35: 45748 | G35: -8 | I35: =VLOOKUP(K35,[1]GRADE!$A:$P,16,FALSE) -> Gold | K35: 2051 | L35: 221
A36: V | B36: ZSSD | C36: SA | D36: 2051223 | E36: 46112 | F36: 45748 | G36: -8 | I36: =VLOOKUP(K36,[1]GRADE!$A:$P,16,FALSE) -> Gold | K36: 2051 | L36: 223
A37: V | B37: ZSSD | C37: SA | D37: 2485254 | E37: 46112 | F37: 45748 | G37: -4 | H37: L29 | I37: =VLOOKUP(K37,[1]GRADE!$A:$P,16,FALSE) -> SILVER | K37: 2485 | L37: 254
A38: V | B38: ZSSD | C38: SA | D38: 2486089 | E38: 46112 | F38: 45748 | G38: -4 | H38: L29 | I38: =VLOOKUP(K38,[1]GRADE!$A:$P,16,FALSE) -> SILVER | K38: 2486 | L38: 89
A39: V | B39: ZSSD | C39: SA | D39: 2486163 | E39: 46112 | F39: 45748 | G39: -4 | H39: L29 | I39: =VLOOKUP(K39,[1]GRADE!$A:$P,16,FALSE) -> SILVER | K39: 2486 | L39: 163
A40: V | B40: ZSSD | C40: SA | D40: 2486164 | E40: 46112 | F40: 45748 | G40: -4 | H40: L29 | I40: =VLOOKUP(K40,[1]GRADE!$A:$P,16,FALSE) -> SILVER | K40: 2486 | L40: 164
A41: V | B41: ZSSD | C41: SA | D41: 2486183 | E41: 46112 | F41: 45748 | G41: -4 | H41: L29 | I41: =VLOOKUP(K41,[1]GRADE!$A:$P,16,FALSE) -> SILVER | K41: 2486 | L41: 183
A42: V | B42: ZSSD | C42: SA | D42: 2486184 | E42: 46112 | F42: 45748 | G42: -4 | H42: L29 | I42: =VLOOKUP(K42,[1]GRADE!$A:$P,16,FALSE) -> SILVER | K42: 2486 | L42: 184
A43: V | B43: ZSSD | C43: SA | D43: 2486189 | E43: 46112 | F43: 45748 | G43: -4 | H43: L29 | I43: =VLOOKUP(K43,[1]GRADE!$A:$P,16,FALSE) -> SILVER | K43: 2486 | L43: 189
A44: V | B44: ZSSD | C44: SA | D44: 2486190 | E44: 46112 | F44: 45748 | G44: -4 | H44: L29 | I44: =VLOOKUP(K44,[1]GRADE!$A:$P,16,FALSE) -> SILVER | K44: 2486 | L44: 190
A45: V | B45: ZSSD | C45: SA | D45: 2510193 | E45: 46112 | F45: 45748 | G45: -5.5 | I45: =VLOOKUP(K45,[1]GRADE!$A:$P,16,FALSE) -> BRONZE | K45: 2510 | L45: 193
A46: V | B46: ZSSD | C46: SA | D46: 2510195 | E46: 46112 | F46: 45748 | G46: -5.5 | I46: =VLOOKUP(K46,[1]GRADE!$A:$P,16,FALSE) -> BRONZE | K46: 2510 | L46: 195
A47: V | B47: ZSSD | C47: SA | D47: 2518183 | E47: 46112 | F47: 45748 | G47: -5.5 | I47: =VLOOKUP(K47,[1]GRADE!$A:$P,16,FALSE) -> SILVER | K47: 2518 | L47: 183
A48: V | B48: ZSSD | C48: SA | D48: 2518184 | E48: 46112 | F48: 45748 | G48: -5.5 | I48: =VLOOKUP(K48,[1]GRADE!$A:$P,16,FALSE) -> SILVER | K48: 2518 | L48: 184
A49: V | B49: ZSSD | C49: SA | D49: 2518251 | E49: 46112 | F49: 45748 | G49: -5.5 | I49: =VLOOKUP(K49,[1]GRADE!$A:$P,16,FALSE) -> SILVER | K49: 2518 | L49: 251
A50: V | B50: ZSSD | C50: SA | D50: 2519183 | E50: 46112 | F50: 45748 | G50: -5.5 | I50: =VLOOKUP(K50,[1]GRADE!$A:$P,16,FALSE) -> SILVER | K50: 2519 | L50: 183
A51: V | B51: ZSSD | C51: SA | D51: 2519184 | E51: 46112 | F51: 45748 | G51: -5.5 | I51: =VLOOKUP(K51,[1]GRADE!$A:$P,16,FALSE) -> SILVER | K51: 2519 | L51: 184
A52: V | B52: ZSSD | C52: SA | D52: 2519187 | E52: 46112 | F52: 45748 | G52: -5.5 | I52: =VLOOKUP(K52,[1]GRADE!$A:$P,16,FALSE) -> SILVER | K52: 2519 | L52: 187
A53: V | B53: ZSSD | C53: SA | D53: 2519188 | E53: 46112 | F53: 45748 | G53: -5.5 | I53: =VLOOKUP(K53,[1]GRADE!$A:$P,16,FALSE) -> SILVER | K53: 2519 | L53: 188
A54: V | B54: ZSSD | C54: SA | D54: 2519242 | E54: 46112 | F54: 45748 | G54: -5.5 | I54: =VLOOKUP(K54,[1]GRADE!$A:$P,16,FALSE) -> SILVER | K54: 2519 | L54: 242
A55: V | B55: ZSSD | C55: SA | D55: 2527163 | E55: 46112 | F55: 45748 | G55: -4 | H55: L29 | I55: =VLOOKUP(K55,[1]GRADE!$A:$P,16,FALSE) -> SILVER | K55: 2527 | L55: 163
A56: V | B56: ZSSD | C56: SA | D56: 2527164 | E56: 46112 | F56: 45748 | G56: -4 | H56: L29 | I56: =VLOOKUP(K56,[1]GRADE!$A:$P,16,FALSE) -> SILVER | K56: 2527 | L56: 164
...

Sheet ZCON
A1: Application | B1: Condition Type | C1: Customer group | D1: Material | E1: Valid to | F1: Valid From | G1: Amount | H1: Unit of measure | I1: oka
A2: V | B2: ZCON | C2: SA | D2: 1000401 | E2: 46112 | F2: 45748 | G2: -6
A3: V | B3: ZCON | C3: SA | D3: 1407401 | E3: 46112 | F3: 45748 | G3: -4 | H3: L29
A4: V | B4: ZCON | C4: SA | D4: 1408401 | E4: 46112 | F4: 45748 | G4: -4 | H4: L29
A5: V | B5: ZCON | C5: SA | D5: 1412401 | E5: 46112 | F5: 45748 | G5: -4 | H5: L29
A6: V | B6: ZCON | C6: SA | D6: 1414401 | E6: 46112 | F6: 45748 | G6: -4 | H6: L29
A7: V | B7: ZCON | C7: SA | D7: 1415401 | E7: 46112 | F7: 45748 | G7: -4 | H7: L29
A8: V | B8: ZCON | C8: SA | D8: 1418401 | E8: 46112 | F8: 45748 | G8: -4 | H8: L29
A9: V | B9: ZCON | C9: SA | D9: 1507401 | E9: 46112 | F9: 45748 | G9: -6
A10: V | B10: ZCON | C10: SA | D10: 1513401 | E10: 46112 | F10: 45748 | G10: -6
A11: V | B11: ZCON | C11: SA | D11: 1514401 | E11: 46112 | F11: 45748 | G11: -6
A12: V | B12: ZCON | C12: SA | D12: 1515401 | E12: 46112 | F12: 45748 | G12: -6
A13: V | B13: ZCON | C13: SA | D13: 1516401 | E13: 46112 | F13: 45748 | G13: -6
A14: V | B14: ZCON | C14: SA | D14: 1517401 | E14: 46112 | F14: 45748 | G14: -6
A15: V | B15: ZCON | C15: SA | D15: 2476401 | E15: 46112 | F15: 45748 | G15: -4 | H15: L29
A16: V | B16: ZCON | C16: SA | D16: 2484401 | E16: 46112 | F16: 45748 | G16: -4 | H16: L29
A17: V | B17: ZCON | C17: SA | D17: 2485401 | E17: 46112 | F17: 45748 | G17: -4 | H17: L29
A18: V | B18: ZCON | C18: SA | D18: 2486401 | E18: 46112 | F18: 45748 | G18: -4 | H18: L29
A19: V | B19: ZCON | C19: SA | D19: 2510401 | E19: 46112 | F19: 45748 | G19: -5.5
A20: V | B20: ZCON | C20: SA | D20: 2518401 | E20: 46112 | F20: 45748 | G20: -5.5
A21: V | B21: ZCON | C21: SA | D21: 2519401 | E21: 46112 | F21: 45748 | G21: -5.5
A22: V | B22: ZCON | C22: SA | D22: 2525401 | E22: 46112 | F22: 45748 | G22: -4 | H22: L29
A23: V | B23: ZCON | C23: SA | D23: 2527401 | E23: 46112 | F23: 45748 | G23: -4 | H23: L29
A24: V | B24: ZCON | C24: SA | D24: 2528401 | E24: 46112 | F24: 45748 | G24: -5.5
A25: V | B25: ZCON | C25: SA | D25: 2540401 | E25: 46112 | F25: 45748 | G25: -5.5
A26: V | B26: ZCON | C26: SA | D26: 2545401 | E26: 46112 | F26: 45748 | G26: -4 | H26: L29
A27: V | B27: ZCON | C27: SA | D27: 2546401 | E27: 46112 | F27: 45748 | G27: -4 | H27: L29
A28: V | B28: ZCON | C28: SA | D28: 2548401 | E28: 46112 | F28: 45748 | G28: -5.5
A29: V | B29: ZCON | C29: SA | D29: 2549401 | E29: 46112 | F29: 45748 | G29: -5.5
A30: V | B30: ZCON | C30: SA | D30: 2554401 | E30: 46112 | F30: 45748 | G30: -4 | H30: L29
A31: V | B31: ZCON | C31: SA | D31: 2557401 | E31: 46112 | F31: 45748 | G31: -5.5
A32: V | B32: ZCON | C32: SA | D32: 2560401 | E32: 46112 | F32: 45748 | G32: -4 | H32: L29
A33: V | B33: ZCON | C33: SA | D33: 2577401 | E33: 46112 | F33: 45748 | G33: -5.5
A34: V | B34: ZCON | C34: SA | D34: 2704401 | E34: 46112 | F34: 45748 | G34: -6
A35: V | B35: ZCON | C35: SA | D35: 2705401 | E35: 46112 | F35: 45748 | G35: -6
A36: V | B36: ZCON | C36: SA | D36: 2706401 | E36: 46112 | F36: 45748 | G36: -6
A37: V | B37: ZCON | C37: SA | D37: 2824401 | E37: 46112 | F37: 45748 | G37: -7
A38: V | B38: ZCON | C38: SA | D38: 2828401 | E38: 46112 | F38: 45748 | G38: -8
A39: V | B39: ZCON | C39: SA | D39: 2829401 | E39: 46112 | F39: 45748 | G39: -8
A40: V | B40: ZCON | C40: SA | D40: 2909401 | E40: 46112 | F40: 45772 | G40: -8
...

Sheet ZAVL
A1: Application | B1: Condition Type | C1: Material | D1: Valid to | E1: Valid From | F1: Amount | G1: Unit of measure | H1: oka
A2: V | B2: ZAVL | C2: 830981014 | D2: 2958465 | E2: 38504 | F2: 102 | G2: EA
A3: V | B3: ZAVL | C3: 838900001 | D3: 2958465 | E3: 42664 | F3: 140 | G3: EA
A4: V | B4: ZAVL | C4: 083890000A | D4: 2958465 | E4: 42401 | F4: 150 | G4: EA
A5: V | B5: ZAVL | C5: 838900044 | D5: 2958465 | E5: 41198 | F5: 1 | G5: EA
A6: V | B6: ZAVL | C6: 838900054 | D6: 2958465 | E6: 37712 | F6: 1 | G6: EA
A7: V | B7: ZAVL | C7: 838900084 | D7: 2958465 | E7: 37841 | F7: 1 | G7: EA
A8: V | B8: ZAVL | C8: 838900104 | D8: 2958465 | E8: 37288 | F8: 1 | G8: EA
A9: V | B9: ZAVL | C9: 838900254 | D9: 2958465 | E9: 38108 | F9: 0.02 | G9: EA
A10: V | B10: ZAVL | C10: 838900454 | D10: 2958465 | E10: 40637 | F10: 0.01 | G10: EA
A11: V | B11: ZAVL | C11: 838900554 | D11: 2958465 | E11: 40634 | F11: 0.01 | G11: EA
A12: V | B12: ZAVL | C12: 838903004 | D12: 2958465 | E12: 37326 | F12: 1 | G12: EA
A13: V | B13: ZAVL | C13: 838904004 | D13: 2958465 | E13: 41613 | F13: 1 | G13: EA
A14: V | B14: ZAVL | C14: 838907004 | D14: 2958465 | E14: 42262 | F14: 0.01 | G14: EA
A15: V | B15: ZAVL | C15: 838920104 | D15: 46142 | E15: 45824 | F15: 3 | G15: EA
A16: V | B16: ZAVL | C16: 838920203 | D16: 2958465 | E16: 45047 | F16: 1 | G16: EA
... A7924: V | B7924: ZAVL | C7924: 9901906 | D7924: 2958465 | E7924: 44431 | F7924: 68.25 | G7924: CAN
A7925: V | B7925: ZAVL | C7925: B49200 | D7925: 2958465 | E7925: 44075 | F7925: 24629 | G7925: TO
A7926: V | B7926: ZAVL | C7926: G16000 | D7926: 2958465 | E7926: 43932 | F7926: 1 | G7926: KL
A7927: V | B7927: ZAVL | C7927: G50000 | D7927: 2958465 | E7927: 43932 | F7927: 1 | G7927: KL
A7928: V | B7928: ZAVL | C7928: M00014 | D7928: 2958465 | E7928: 38322 | F7928: 1 | G7928: EA
A7929: V | B7929: ZAVL | C7929: M00028 | D7929: 2958465 | E7929: 40800 | F7929: 1 | G7929: EA
A7930: V | B7930: ZAVL | C7930: M00032 | D7930: 2958465 | E7930: 40800 | F7930: 1 | G7930: EA
A7931: V | B7931: ZAVL | C7931: M00040 | D7931: 2958465 | E7931: 39202 | F7931: 1 | G7931: EA
A7932: V | B7932: ZAVL | C7932: M00046 | D7932: 2958465 | E7932: 37834 | F7932: 1 | G7932: EA
A7933: V | B7933: ZAVL | C7933: M00047 | D7933: 2958465 | E7933: 37834 | F7933: 1 | G7933: EA
A7934: V | B7934: ZAVL | C7934: M00066 | D7934: 2958465 | E7934: 40044 | F7934: 1 | G7934: EA

Sheet SMALL PACK
A1: Material | B1: MAT | C1: PACK CODE | D1: Type | E1: Material Description | F1: PACK SIZE in L | G1: Item Size in L | H1: No of items in one pack | I1: MRP/item | J1: MRP/L | K1: DLP conv | L1: DLP/ITEM | M1: DLP/L | N1: RSP/ITEM | O1: RSP/L | P1: HO DISC/L | Q1: UPHAAR UTSAV/L | R1: MSS/L | S1: TOTAL DISCOUNT /item | T1: Discounted RSP/ITEM | U1: EDLP/item | V1: EDLP/L | W1: EDLP/PACK | X1: Margin/item | Y1: Margin/pack | Z1: Margin/L | AA1: Stockist Discount % | AB1: Stockist Discount/ITEM | AC1: Cash Discount | AD1: Cash Discount/ITEM | AE1: Stockist Discount/L | AF1: Cash Discount/L | AH1: CATEGORY
A2: 1404174 | B2: =VALUE(LEFT(A2,4)) -> 1404 | C2: =VALUE(RIGHT(A2,3)) -> 174 | D2: =VLOOKUP(C2,Sheet1!$A$2:$K$369991,11,0) -> CAR | E2: SERVO PRIDE 40 - 40x1/2L - HDPE | F2: =VLOOKUP(C2,'PACK MASTER'!$A$2:$I$512998,9,0)*1000 -> 20 | G2: =VLOOKUP(C2,'PACK MASTER'!$A$2:$G$512998,7,0) -> 0.5 | H2: =F2/G2 -> 40 | I2: =VLOOKUP($A2,ZMRP!$C$2:$F$99995,4,0) -> 183 | J2: =I2/G2 -> 366 | K2: =VLOOKUP($A2,ZLAM!$C$2:$F$99999,4,0) -> 78.68 | L2: =I2*K2/100 -> 143.9844 | M2: =L2/G2 -> 287.9688 | N2: =L2/1.18 -> 122.02068 | O2: =N2/G2 -> 244.04136 | P2: =IFERROR(ABS(VLOOKUP($A2,ZTRV!$D$2:$G$99407,4,0)),0) -> 0 | Q2: =IFERROR(ABS(VLOOKUP($A2,ZTR1!$D$2:$G$99999,4,0)),0) -> 0 | R2: =IFERROR(ABS(VLOOKUP($A2,ZTR2!$D$2:$G$99939,4,0)),0) -> 0 | S2: =SUM(P2:R2)*G2 -> 0 | T2: =N2-S2 -> 122.02068 | U2: =T2*1.18 -> 143.9844 | V2: =U2/G2 -> 287.9688 | W2: =V2*F2 -> 5759.376 | X2: =I2-U2 -> 39.0156 | Y2: =X2*H2 -> 1560.624 | Z2: =J2-V2 -> 78.0312 | AA2: =IFERROR(ABS(VLOOKUP(A2,ZSSD!$D$2:$G$99933,4,0)),AI2) -> 6.5 | AB2: =IFERROR(IF(VLOOKUP(A2,ZSSD!$D:$H,5,0)="L29",AA2*G2,AA2*L2/100),AA2*L2/100) -> 9.358986 | AC2: 2 | AD2: =2*(T2-AB2)/100 -> 2.2532338 | AE2: =+AB2/G2 -> 18.717972 | AF2: =+AD2/G2 -> 4.5064677 | AG2: =VLOOKUP(A2,ZSSD!D:D,1,0) -> #N/A | AH2: =VLOOKUP(B2,[2]GRADE!$A:$P,16,0) -> SILVER | AI2: =IF(AH2="SILVER",6.5,IF(AH2="GOLD",8,IF(AH2="INDUSTRIAL",6,IF(AH2="GREEN",7,IF(AH2="BRONZE",5.5,0))))) -> 6.5
A3: 1404184 | B3: =VALUE(LEFT(A3,4)) -> 1404 | C3: =VALUE(RIGHT(A3,3)) -> 184 | D3: =VLOOKUP(C3,Sheet1!$A$2:$K$369991,11,0) -> CAR | E3: SERVO PRIDE 40 - 20x1L - HDPE | F3: =VLOOKUP(C3,'PACK MASTER'!$A$2:$I$512998,9,0)*1000 -> 20 | G3: =VLOOKUP(C3,'PACK MASTER'!$A$2:$G$512998,7,0) -> 1 | H3: =F3/G3 -> 20 | I3: =VLOOKUP($A3,ZMRP!$C$2:$F$99995,4,0) -> 355 | J3: =I3/G3 -> 355 | K3: =VLOOKUP($A3,ZLAM!$C$2:$F$99999,4,0) -> 79.24 | L3: =I3*K3/100 -> 281.302 | M3: =L3/G3 -> 281.302 | N3: =L3/1.18 -> 238.39153 | O3: =N3/G3 -> 238.39153 | P3: =IFERROR(ABS(VLOOKUP($A3,ZTRV!$D$2:$G$99407,4,0)),0) -> 8 | Q3: =IFERROR(ABS(VLOOKUP($A3,ZTR1!$D$2:$G$99999,4,0)),0) -> 0 | R3: =IFERROR(ABS(VLOOKUP($A3,ZTR2!$D$2:$G$99939,4,0)),0) -> 0 | S3: =SUM(P3:R3)*G3 -> 8 | T3: =N3-S3 -> 230.39153 | U3: =T3*1.18 -> 271.862 | V3: =U3/G3 -> 271.862 | W3: =V3*F3 -> 5437.24 | X3: =I3-U3 -> 83.138 | Y3: =X3*H3 -> 1662.76 | Z3: =J3-V3 -> 83.138 | AA3: =IFERROR(ABS(VLOOKUP(A3,ZSSD!$D$2:$G$99933,4,0)),AI3) -> 6.5 | AB3: =IFERROR(IF(VLOOKUP(A3,ZSSD!$D:$H,5,0)="L29",AA3*G3,AA3*L3/100),AA3*L3/100) -> 18.28463 | AC3: 2 | AD3: =2*(T3-AB3)/100 -> 4.2421379 | AE3: =+AB3/G3 -> 18.28463 | AF3: =+AD3/G3 -> 4.2421379 | AG3: =VLOOKUP(A3,ZSSD!D:D,1,0) -> #N/A | AH3: =VLOOKUP(B3,[2]GRADE!$A:$P,16,0) -> SILVER | AI3: =IF(AH3="SILVER",6.5,IF(AH3="GOLD",8,IF(AH3="INDUSTRIAL",6,IF(AH3="GREEN",7,IF(AH3="BRONZE",5.5,0))))) -> 6.5
A4: 1404229 | B4: =VALUE(LEFT(A4,4)) -> 1404 | C4: =VALUE(RIGHT(A4,3)) -> 229 | D4: =VLOOKUP(C4,Sheet1!$A$2:$K$369991,11,0) -> CAR | E4: SERVO PRIDE 40-20 X 1 L PROMO | F4: =VLOOKUP(C4,'PACK MASTER'!$A$2:$I$512998,9,0)*1000 -> 20 | G4: =VLOOKUP(C4,'PACK MASTER'!$A$2:$G$512998,7,0) -> 1 | H4: =F4/G4 -> 20 | I4: =VLOOKUP($A4,ZMRP!$C$2:$F$99995,4,0) -> 355 | J4: =I4/G4 -> 355 | K4: =VLOOKUP($A4,ZLAM!$C$2:$F$99999,4,0) -> 79.24 | L4: =I4*K4/100 -> 281.302 | M4: =L4/G4 -> 281.302 | N4: =L4/1.18 -> 238.39153 | O4: =N4/G4 -> 238.39153 | P4: =IFERROR(ABS(VLOOKUP($A4,ZTRV!$D$2:$G$99407,4,0)),0) -> 0 | Q4: =IFERROR(ABS(VLOOKUP($A4,ZTR1!$D$2:$G$99999,4,0)),0) -> 0 | R4: =IFERROR(ABS(VLOOKUP($A4,ZTR2!$D$2:$G$99939,4,0)),0) -> 0 | S4: =SUM(P4:R4)*G4 -> 0 | T4: =N4-S4 -> 238.39153 | U4: =T4*1.18 -> 281.302 | V4: =U4/G4 -> 281.302 | W4: =V4*F4 -> 5626.04 | X4: =I4-U4 -> 73.698 | Y4: =X4*H4 -> 1473.96 | Z4: =J4-V4 -> 73.698 | AA4: =IFERROR(ABS(VLOOKUP(A4,ZSSD!$D$2:$G$99933,4,0)),AI4) -> 6.5 | AB4: =IFERROR(IF(VLOOKUP(A4,ZSSD!$D:$H,5,0)="L29",AA4*G4,AA4*L4/100),AA4*L4/100) -> 18.28463 | AC4: 2 | AD4: =2*(T4-AB4)/100 -> 4.4021379 | AE4: =+AB4/G4 -> 18.28463 | AF4: =+AD4/G4 -> 4.4021379 | AG4: =VLOOKUP(A4,ZSSD!D:D,1,0) -> #N/A | AH4: =VLOOKUP(B4,[2]GRADE!$A:$P,16,0) -> SILVER | AI4: =IF(AH4="SILVER",6.5,IF(AH4="GOLD",8,IF(AH4="INDUSTRIAL",6,IF(AH4="GREEN",7,IF(AH4="BRONZE",5.5,0))))) -> 6.5
A5: 1404234 | B5: =VALUE(LEFT(A5,4)) -> 1404 | C5: =VALUE(RIGHT(A5,3)) -> 234 | D5: =VLOOKUP(C5,Sheet1!$A$2:$K$369991,11,0) -> CAR | E5: SERVO PRIDE 40 - 4x5L - HDPE | F5: =VLOOKUP(C5,'PACK MASTER'!$A$2:$I$512998,9,0)*1000 -> 20 | G5: =VLOOKUP(C5,'PACK MASTER'!$A$2:$G$512998,7,0) -> 5 | H5: =F5/G5 -> 4 | I5: =VLOOKUP($A5,ZMRP!$C$2:$F$99995,4,0) -> 1775 | J5: =I5/G5 -> 355 | K5: =VLOOKUP($A5,ZLAM!$C$2:$F$99999,4,0) -> 78.16 | L5: =I5*K5/100 -> 1387.34 | M5: =L5/G5 -> 277.468 | N5: =L5/1.18 -> 1175.7119 | O5: =N5/G5 -> 235.14237 | P5: =IFERROR(ABS(VLOOKUP($A5,ZTRV!$D$2:$G$99407,4,0)),0) -> 8 | Q5: =IFERROR(ABS(VLOOKUP($A5,ZTR1!$D$2:$G$99999,4,0)),0) -> 0 | R5: =IFERROR(ABS(VLOOKUP($A5,ZTR2!$D$2:$G$99939,4,0)),0) -> 0 | S5: =SUM(P5:R5)*G5 -> 40 | T5: =N5-S5 -> 1135.7119 | U5: =T5*1.18 -> 1340.14 | V5: =U5/G5 -> 268.028 | W5: =V5*F5 -> 5360.56 | X5: =I5-U5 -> 434.86 | Y5: =X5*H5 -> 1739.44 | Z5: =J5-V5 -> 86.972 | AA5: =IFERROR(ABS(VLOOKUP(A5,ZSSD!$D$2:$G$99933,4,0)),AI5) -> 6.5 | AB5: =IFERROR(IF(VLOOKUP(A5,ZSSD!$D:$H,5,0)="L29",AA5*G5,AA5*L5/100),AA5*L5/100) -> 90.1771 | AC5: 2 | AD5: =2*(T5-AB5)/100 -> 20.910695 | AE5: =+AB5/G5 -> 18.03542 | AF5: =+AD5/G5 -> 4.1821391 | AG5: =VLOOKUP(A5,ZSSD!D:D,1,0) -> #N/A | AH5: =VLOOKUP(B5,[2]GRADE!$A:$P,16,0) -> SILVER | AI5: =IF(AH5="SILVER",6.5,IF(AH5="GOLD",8,IF(AH5="INDUSTRIAL",6,IF(AH5="GREEN",7,IF(AH5="BRONZE",5.5,0))))) -> 6.5
A6: 1404240 | B6: =VALUE(LEFT(A6,4)) -> 1404 | C6: =VALUE(RIGHT(A6,3)) -> 240 | D6: =VLOOKUP(C6,Sheet1!$A$2:$K$369991,11,0) -> CAR | E6: SERVO PRIDE 40-4x5L - PROMO | F6: =VLOOKUP(C6,'PACK MASTER'!$A$2:$I$512998,9,0)*1000 -> 20 | G6: =VLOOKUP(C6,'PACK MASTER'!$A$2:$G$512998,7,0) -> 5 | H6: =F6/G6 -> 4 | I6: =VLOOKUP($A6,ZMRP!$C$2:$F$99995,4,0) -> 1775 | J6: =I6/G6 -> 355 | K6: =VLOOKUP($A6,ZLAM!$C$2:$F$99999,4,0) -> 78.16 | L6: =I6*K6/100 -> 1387.34 | M6: =L6/G6 -> 277.468 | N6: =L6/1.18 -> 1175.7119 | O6: =N6/G6 -> 235.14237 | P6: =IFERROR(ABS(VLOOKUP($A6,ZTRV!$D$2:$G$99407,4,0)),0) -> 0 | Q6: =IFERROR(ABS(VLOOKUP($A6,ZTR1!$D$2:$G$99999,4,0)),0) -> 0 | R6: =IFERROR(ABS(VLOOKUP($A6,ZTR2!$D$2:$G$99939,4,0)),0) -> 0 | S6: =SUM(P6:R6)*G6 -> 0 | T6: =N6-S6 -> 1175.7119 | U6: =T6*1.18 -> 1387.34 | V6: =U6/G6 -> 277.468 | W6: =V6*F6 -> 5549.36 | X6: =I6-U6 -> 387.66 | Y6: =X6*H6 -> 1550.64 | Z6: =J6-V6 -> 77.532 | AA6: =IFERROR(ABS(VLOOKUP(A6,ZSSD!$D$2:$G$99933,4,0)),AI6) -> 6.5 | AB6: =IFERROR(IF(VLOOKUP(A6,ZSSD!$D:$H,5,0)="L29",AA6*G6,AA6*L6/100),AA6*L6/100) -> 90.1771 | AC6: 2 | AD6: =2*(T6-AB6)/100 -> 21.710695 | AE6: =+AB6/G6 -> 18.03542 | AF6: =+AD6/G6 -> 4.3421391 | AG6: =VLOOKUP(A6,ZSSD!D:D,1,0) -> #N/A | AH6: =VLOOKUP(B6,[2]GRADE!$A:$P,16,0) -> SILVER | AI6: =IF(AH6="SILVER",6.5,IF(AH6="GOLD",8,IF(AH6="INDUSTRIAL",6,IF(AH6="GREEN",7,IF(AH6="BRONZE",5.5,0))))) -> 6.5
A7: 1404242 | B7: =VALUE(LEFT(A7,4)) -> 1404 | C7: =VALUE(RIGHT(A7,3)) -> 242 | D7: =VLOOKUP(C7,Sheet1!$A$2:$K$369991,11,0) -> BUC | E7: SERVO PRIDE 40 - 10L BUC | F7: =VLOOKUP(C7,'PACK MASTER'!$A$2:$I$512998,9,0)*1000 -> 10 | G7: =VLOOKUP(C7,'PACK MASTER'!$A$2:$G$512998,7,0) -> 10 | H7: =F7/G7 -> 1 | I7: =VLOOKUP($A7,ZMRP!$C$2:$F$99995,4,0) -> 3550 | J7: =I7/G7 -> 355 | K7: =VLOOKUP($A7,ZLAM!$C$2:$F$99999,4,0) -> 77.84 | L7: =I7*K7/100 -> 2763.32 | M7: =L7/G7 -> 276.332 | N7: =L7/1.18 -> 2341.7966 | O7: =N7/G7 -> 234.17966 | P7: =IFERROR(ABS(VLOOKUP($A7,ZTRV!$D$2:$G$99407,4,0)),0) -> 8 | Q7: =IFERROR(ABS(VLOOKUP($A7,ZTR1!$D$2:$G$99999,4,0)),0) -> 0 | R7: =IFERROR(ABS(VLOOKUP($A7,ZTR2!$D$2:$G$99939,4,0)),0) -> 0 | S7: =SUM(P7:R7)*G7 -> 80 | T7: =N7-S7 -> 2261.7966 | U7: =T7*1.18 -> 2668.92 | V7: =U7/G7 -> 266.892 | W7: =V7*F7 -> 2668.92 | X7: =I7-U7 -> 881.08 | Y7: =X7*H7 -> 881.08 | Z7: =J7-V7 -> 88.108 | AA7: =IFERROR(ABS(VLOOKUP(A7,ZSSD!$D$2:$G$99933,4,0)),AI7) -> 6.5 | AB7: =IFERROR(IF(VLOOKUP(A7,ZSSD!$D:$H,5,0)="L29",AA7*G7,AA7*L7/100),AA7*L7/100) -> 179.6158 | AC7: 2 | AD7: =2*(T7-AB7)/100 -> 41.643616 | AE7: =+AB7/G7 -> 17.96158 | AF7: =+AD7/G7 -> 4.1643616 | AG7: =VLOOKUP(A7,ZSSD!D:D,1,0) -> #N/A | AH7: =VLOOKUP(B7,[2]GRADE!$A:$P,16,0) -> SILVER | AI7: =IF(AH7="SILVER",6.5,IF(AH7="GOLD",8,IF(AH7="INDUSTRIAL",6,IF(AH7="GREEN",7,IF(AH7="BRONZE",5.5,0))))) -> 6.5
A8: 1404265 | B8: =VALUE(LEFT(A8,4)) -> 1404 | C8: =VALUE(RIGHT(A8,3)) -> 265 | D8: =VLOOKUP(C8,Sheet1!$A$2:$K$369991,11,0) -> BUC | E8: SERVO PRIDE 40-20L BUC | F8: =VLOOKUP(C8,'PACK MASTER'!$A$2:$I$512998,9,0)*1000 -> 20 | G8: =VLOOKUP(C8,'PACK MASTER'!$A$2:$G$512998,7,0) -> 20 | H8: =F8/G8 -> 1 | I8: =VLOOKUP($A8,ZMRP!$C$2:$F$99995,4,0) -> 6900 | J8: =I8/G8 -> 345 | K8: =VLOOKUP($A8,ZLAM!$C$2:$F$99999,4,0) -> 79.31 | L8: =I8*K8/100 -> 5472.39 | M8: =L8/G8 -> 273.6195 | N8: =L8/1.18 -> 4637.6186 | O8: =N8/G8 -> 231.88093 | P8: =IFERROR(ABS(VLOOKUP($A8,ZTRV!$D$2:$G$99407,4,0)),0) -> 8 | Q8: =IFERROR(ABS(VLOOKUP($A8,ZTR1!$D$2:$G$99999,4,0)),0) -> 0 | R8: =IFERROR(ABS(VLOOKUP($A8,ZTR2!$D$2:$G$99939,4,0)),0) -> 0 | S8: =SUM(P8:R8)*G8 -> 160 | T8: =N8-S8 -> 4477.6186 | U8: =T8*1.18 -> 5283.59 | V8: =U8/G8 -> 264.1795 | W8: =V8*F8 -> 5283.59 | X8: =I8-U8 -> 1616.41 | Y8: =X8*H8 -> 1616.41 | Z8: =J8-V8 -> 80.8205 | AA8: =IFERROR(ABS(VLOOKUP(A8,ZSSD!$D$2:$G$99933,4,0)),AI8) -> 6.5 | AB8: =IFERROR(IF(VLOOKUP(A8,ZSSD!$D:$H,5,0)="L29",AA8*G8,AA8*L8/100),AA8*L8/100) -> 355.70535 | AC8: 2 | AD8: =2*(T8-AB8)/100 -> 82.438266 | AE8: =+AB8/G8 -> 17.785267 | AF8: =+AD8/G8 -> 4.1219133 | AG8: =VLOOKUP(A8,ZSSD!D:D,1,0) -> #N/A | AH8: =VLOOKUP(B8,[2]GRADE!$A:$P,16,0) -> SILVER | AI8: =IF(AH8="SILVER",6.5,IF(AH8="GOLD",8,IF(AH8="INDUSTRIAL",6,IF(AH8="GREEN",7,IF(AH8="BRONZE",5.5,0))))) -> 6.5
A9: 1408164 | B9: =VALUE(LEFT(A9,4)) -> 1408 | C9: =VALUE(RIGHT(A9,3)) -> 164 | D9: =VLOOKUP(C9,Sheet1!$A$2:$K$369991,11,0) -> CAR | E9: MAXIMILE PREMIUM-40X1/4L | F9: =VLOOKUP(C9,'PACK MASTER'!$A$2:$I$512998,9,0)*1000 -> 10 | G9: =VLOOKUP(C9,'PACK MASTER'!$A$2:$G$512998,7,0) -> 0.25 | H9: =F9/G9 -> 40 | I9: =VLOOKUP($A9,ZMRP!$C$2:$F$99995,4,0) -> 74 | J9: =I9/G9 -> 296 | K9: =VLOOKUP($A9,ZLAM!$C$2:$F$99999,4,0) -> 77.72 | L9: =I9*K9/100 -> 57.5128 | M9: =L9/G9 -> 230.0512 | N9: =L9/1.18 -> 48.739661 | O9: =N9/G9 -> 194.95864 | P9: =IFERROR(ABS(VLOOKUP($A9,ZTRV!$D$2:$G$99407,4,0)),0) -> 0 | Q9: =IFERROR(ABS(VLOOKUP($A9,ZTR1!$D$2:$G$99999,4,0)),0) -> 0 | R9: =IFERROR(ABS(VLOOKUP($A9,ZTR2!$D$2:$G$99939,4,0)),0) -> 0 | S9: =SUM(P9:R9)*G9 -> 0 | T9: =N9-S9 -> 48.739661 | U9: =T9*1.18 -> 57.5128 | V9: =U9/G9 -> 230.0512 | W9: =V9*F9 -> 2300.512 | X9: =I9-U9 -> 16.4872 | Y9: =X9*H9 -> 659.488 | Z9: =J9-V9 -> 65.9488 | AA9: =IFERROR(ABS(VLOOKUP(A9,ZSSD!$D$2:$G$99933,4,0)),AI9) -> 4 | AB9: =IFERROR(IF(VLOOKUP(A9,ZSSD!$D:$H,5,0)="L29",AA9*G9,AA9*L9/100),AA9*L9/100) -> 1 | AC9: 2 | AD9: =2*(T9-AB9)/100 -> 0.95479322 | AE9: =+AB9/G9 -> 4 | AF9: =+AD9/G9 -> 3.8191729 | AG9: =VLOOKUP(A9,ZSSD!D:D,1,0) -> 1408164 | AH9: =VLOOKUP(B9,[2]GRADE!$A:$P,16,0) -> SILVER | AI9: =IF(AH9="SILVER",6.5,IF(AH9="GOLD",8,IF(AH9="INDUSTRIAL",6,IF(AH9="GREEN",7,IF(AH9="BRONZE",5.5,0))))) -> 6.5
A10: 1408184 | B10: =VALUE(LEFT(A10,4)) -> 1408 | C10: =VALUE(RIGHT(A10,3)) -> 184 | D10: =VLOOKUP(C10,Sheet1!$A$2:$K$369991,11,0) -> CAR | E10: MAXIMILE PREMIUM - 20 X 1 L HDPE | F10: =VLOOKUP(C10,'PACK MASTER'!$A$2:$I$512998,9,0)*1000 -> 20 | G10: =VLOOKUP(C10,'PACK MASTER'!$A$2:$G$512998,7,0) -> 1 | H10: =F10/G10 -> 20 | I10: =VLOOKUP($A10,ZMRP!$C$2:$F$99995,4,0) -> 262 | J10: =I10/G10 -> 262 | K10: =VLOOKUP($A10,ZLAM!$C$2:$F$99999,4,0) -> 78.76 | L10: =I10*K10/100 -> 206.3512 | M10: =L10/G10 -> 206.3512 | N10: =L10/1.18 -> 174.8739 | O10: =N10/G10 -> 174.8739 | P10: =IFERROR(ABS(VLOOKUP($A10,ZTRV!$D$2:$G$99407,4,0)),0) -> 0 | Q10: =IFERROR(ABS(VLOOKUP($A10,ZTR1!$D$2:$G$99999,4,0)),0) -> 0 | R10: =IFERROR(ABS(VLOOKUP($A10,ZTR2!$D$2:$G$99939,4,0)),0) -> 0 | S10: =SUM(P10:R10)*G10 -> 0 | T10: =N10-S10 -> 174.8739 | U10: =T10*1.18 -> 206.3512 | V10: =U10/G10 -> 206.3512 | W10: =V10*F10 -> 4127.024 | X10: =I10-U10 -> 55.6488 | Y10: =X10*H10 -> 1112.976 | Z10: =J10-V10 -> 55.6488 | AA10: =IFERROR(ABS(VLOOKUP(A10,ZSSD!$D$2:$G$99933,4,0)),AI10) -> 4 | AB10: =IFERROR(IF(VLOOKUP(A10,ZSSD!$D:$H,5,0)="L29",AA10*G10,AA10*L10/100),AA10*L10/100) -> 4 | AC10: 2 | AD10: =2*(T10-AB10)/100 -> 3.417478 | AE10: =+AB10/G10 -> 4 | AF10: =+AD10/G10 -> 3.417478 | AG10: =VLOOKUP(A10,ZSSD!D:D,1,0) -> 1408184 | AH10: =VLOOKUP(B10,[2]GRADE!$A:$P,16,0) -> SILVER | AI10: =IF(AH10="SILVER",6.5,IF(AH10="GOLD",8,IF(AH10="INDUSTRIAL",6,IF(AH10="GREEN",7,IF(AH10="BRONZE",5.5,0))))) -> 6.5
A11: 1408244 | B11: =VALUE(LEFT(A11,4)) -> 1408 | C11: =VALUE(RIGHT(A11,3)) -> 244 | D11: =VLOOKUP(C11,Sheet1!$A$2:$K$369991,11,0) -> CAR | E11: MAXIMILE PREMIUM - 4 X 6 L HDPE | F11: =VLOOKUP(C11,'PACK MASTER'!$A$2:$I$512998,9,0)*1000 -> 24 | G11: =VLOOKUP(C11,'PACK MASTER'!$A$2:$G$512998,7,0) -> 6 | H11: =F11/G11 -> 4 | I11: =VLOOKUP($A11,ZMRP!$C$2:$F$99995,4,0) -> 1572 | J11: =I11/G11 -> 262 | K11: =VLOOKUP($A11,ZLAM!$C$2:$F$99999,4,0) -> 76.49 | L11: =I11*K11/100 -> 1202.4228 | M11: =L11/G11 -> 200.4038 | N11: =L11/1.18 -> 1019.0024 | O11: =N11/G11 -> 169.83373 | P11: =IFERROR(ABS(VLOOKUP($A11,ZTRV!$D$2:$G$99407,4,0)),0) -> 0 | Q11: =IFERROR(ABS(VLOOKUP($A11,ZTR1!$D$2:$G$99999,4,0)),0) -> 0 | R11: =IFERROR(ABS(VLOOKUP($A11,ZTR2!$D$2:$G$99939,4,0)),0) -> 0 | S11: =SUM(P11:R11)*G11 -> 0 | T11: =N11-S11 -> 1019.0024 | U11: =T11*1.18 -> 1202.4228 | V11: =U11/G11 -> 200.4038 | W11: =V11*F11 -> 4809.6912 | X11: =I11-U11 -> 369.5772 | Y11: =X11*H11 -> 1478.3088 | Z11: =J11-V11 -> 61.5962 | AA11: =IFERROR(ABS(VLOOKUP(A11,ZSSD!$D$2:$G$99933,4,0)),AI11) -> 4 | AB11: =IFERROR(IF(VLOOKUP(A11,ZSSD!$D:$H,5,0)="L29",AA11*G11,AA11*L11/100),AA11*L11/100) -> 24 | AC11: 2 | AD11: =2*(T11-AB11)/100 -> 19.900047 | AE11: =+AB11/G11 -> 4 | AF11: =+AD11/G11 -> 3.3166746 | AG11: =VLOOKUP(A11,ZSSD!D:D,1,0) -> 1408244 | AH11: =VLOOKUP(B11,[2]GRADE!$A:$P,16,0) -> SILVER | AI11: =IF(AH11="SILVER",6.5,IF(AH11="GOLD",8,IF(AH11="INDUSTRIAL",6,IF(AH11="GREEN",7,IF(AH11="BRONZE",5.5,0))))) -> 6.5
A12: 1412184 | B12: =VALUE(LEFT(A12,4)) -> 1412 | C12: =VALUE(RIGHT(A12,3)) -> 184 | D12: =VLOOKUP(C12,Sheet1!$A$2:$K$369991,11,0) -> CAR | E12: MAXIMILE 6K - 20 X 1 L HDPE | F12: =VLOOKUP(C12,'PACK MASTER'!$A$2:$I$512998,9,0)*1000 -> 20 | G12: =VLOOKUP(C12,'PACK MASTER'!$A$2:$G$512998,7,0) -> 1 | H12: =F12/G12 -> 20 | I12: =VLOOKUP($A12,ZMRP!$C$2:$F$99995,4,0) -> 284 | J12: =I12/G12 -> 284 | K12: =VLOOKUP($A12,ZLAM!$C$2:$F$99999,4,0) -> 74.04 | L12: =I12*K12/100 -> 210.2736 | M12: =L12/G12 -> 210.2736 | N12: =L12/1.18 -> 178.19797 | O12: =N12/G12 -> 178.19797 | P12: =IFERROR(ABS(VLOOKUP($A12,ZTRV!$D$2:$G$99407,4,0)),0) -> 0 | Q12: =IFERROR(ABS(VLOOKUP($A12,ZTR1!$D$2:$G$99999,4,0)),0) -> 0 | R12: =IFERROR(ABS(VLOOKUP($A12,ZTR2!$D$2:$G$99939,4,0)),0) -> 0 | S12: =SUM(P12:R12)*G12 -> 0 | T12: =N12-S12 -> 178.19797 | U12: =T12*1.18 -> 210.2736 | V12: =U12/G12 -> 210.2736 | W12: =V12*F12 -> 4205.472 | X12: =I12-U12 -> 73.7264 | Y12: =X12*H12 -> 1474.528 | Z12: =J12-V12 -> 73.7264 | AA12: =IFERROR(ABS(VLOOKUP(A12,ZSSD!$D$2:$G$99933,4,0)),AI12) -> 4 | AB12: =IFERROR(IF(VLOOKUP(A12,ZSSD!$D:$H,5,0)="L29",AA12*G12,AA12*L12/100),AA12*L12/100) -> 4 | AC12: 2 | AD12: =2*(T12-AB12)/100 -> 3.4839593 | AE12: =+AB12/G12 -> 4 | AF12: =+AD12/G12 -> 3.4839593 | AG12: =VLOOKUP(A12,ZSSD!D:D,1,0) -> 1412184 | AH12: =VLOOKUP(B12,[2]GRADE!$A:$P,16,0) -> SILVER | AI12: =IF(AH12="SILVER",6.5,IF(AH12="GOLD",8,IF(AH12="INDUSTRIAL",6,IF(AH12="GREEN",7,IF(AH12="BRONZE",5.5,0))))) -> 6.5
A13: 1412197 | B13: =VALUE(LEFT(A13,4)) -> 1412 | C13: =VALUE(RIGHT(A13,3)) -> 197 | D13: =VLOOKUP(C13,Sheet1!$A$2:$K$369991,11,0) -> CAR | E13: MAXIMILE 6K - 10 X 2 L HDPE | F13: =VLOOKUP(C13,'PACK MASTER'!$A$2:$I$512998,9,0)*1000 -> 20 | G13: =VLOOKUP(C13,'PACK MASTER'!$A$2:$G$512998,7,0) -> 2 | H13: =F13/G13 -> 10 | I13: =VLOOKUP($A13,ZMRP!$C$2:$F$99995,4,0) -> 560 | J13: =I13/G13 -> 280 | K13: =VLOOKUP($A13,ZLAM!$C$2:$F$99999,4,0) -> 74.04 | L13: =I13*K13/100 -> 414.624 | M13: =L13/G13 -> 207.312 | N13: =L13/1.18 -> 351.37627 | O13: =N13/G13 -> 175.68814 | P13: =IFERROR(ABS(VLOOKUP($A13,ZTRV!$D$2:$G$99407,4,0)),0) -> 0 | Q13: =IFERROR(ABS(VLOOKUP($A13,ZTR1!$D$2:$G$99999,4,0)),0) -> 0 | R13: =IFERROR(ABS(VLOOKUP($A13,ZTR2!$D$2:$G$99939,4,0)),0) -> 0 | S13: =SUM(P13:R13)*G13 -> 0 | T13: =N13-S13 -> 351.37627 | U13: =T13*1.18 -> 414.624 | V13: =U13/G13 -> 207.312 | W13: =V13*F13 -> 4146.24 | X13: =I13-U13 -> 145.376 | Y13: =X13*H13 -> 1453.76 | Z13: =J13-V13 -> 72.688 | AA13: =IFERROR(ABS(VLOOKUP(A13,ZSSD!$D$2:$G$99933,4,0)),AI13) -> 4 | AB13: =IFERROR(IF(VLOOKUP(A13,ZSSD!$D:$H,5,0)="L29",AA13*G13,AA13*L13/100),AA13*L13/100) -> 8 | AC13: 2 | AD13: =2*(T13-AB13)/100 -> 6.8675254 | AE13: =+AB13/G13 -> 4 | AF13: =+AD13/G13 -> 3.4337627 | AG13: =VLOOKUP(A13,ZSSD!D:D,1,0) -> 1412197 | AH13: =VLOOKUP(B13,[2]GRADE!$A:$P,16,0) -> SILVER | AI13: =IF(AH13="SILVER",6.5,IF(AH13="GOLD",8,IF(AH13="INDUSTRIAL",6,IF(AH13="GREEN",7,IF(AH13="BRONZE",5.5,0))))) -> 6.5
... A53: 2825022 | B53: =VALUE(LEFT(A53,4)) -> 2825 | C53: =VALUE(RIGHT(A53,3)) -> 22 | D53: =VLOOKUP(C53,Sheet1!$A$2:$K$369991,11,0) -> CAR | E53: SERVO HYPERSPORT F5-10 X 1.2 L PROMO | F53: =VLOOKUP(C53,'PACK MASTER'!$A$2:$I$512998,9,0)*1000 -> 12 | G53: =VLOOKUP(C53,'PACK MASTER'!$A$2:$G$512998,7,0) -> 1.2 | H53: =F53/G53 -> 10 | I53: =VLOOKUP($A53,ZMRP!$C$2:$F$99995,4,0) -> 1054 | J53: =I53/G53 -> 878.33333 | K53: =VLOOKUP($A53,ZLAM!$C$2:$F$99999,4,0) -> 73.5 | L53: =I53*K53/100 -> 774.69 | M53: =L53/G53 -> 645.575 | N53: =L53/1.18 -> 656.51695 | O53: =N53/G53 -> 547.09746 | P53: =IFERROR(ABS(VLOOKUP($A53,ZTRV!$D$2:$G$99407,4,0)),0) -> 40 | Q53: =IFERROR(ABS(VLOOKUP($A53,ZTR1!$D$2:$G$99999,4,0)),0) -> 200 | R53: =IFERROR(ABS(VLOOKUP($A53,ZTR2!$D$2:$G$99939,4,0)),0) -> 0 | S53: =SUM(P53:R53)*G53 -> 288 | T53: =N53-S53 -> 368.51695 | U53: =T53*1.18 -> 434.85 | V53: =U53/G53 -> 362.375 | W53: =V53*F53 -> 4348.5 | X53: =I53-U53 -> 619.15 | Y53: =X53*H53 -> 6191.5 | Z53: =J53-V53 -> 515.95833 | AA53: =IFERROR(ABS(VLOOKUP(A53,ZSSD!$D$2:$G$99933,4,0)),AI53) -> 8 | AB53: =IFERROR(IF(VLOOKUP(A53,ZSSD!$D:$H,5,0)="L29",AA53*G53,AA53*L53/100),AA53*L53/100) -> 61.9752 | AC53: 2 | AD53: =2*(T53-AB53)/100 -> 6.130835 | AE53: =+AB53/G53 -> 51.646 | AF53: =+AD53/G53 -> 5.1090292 | AG53: =VLOOKUP(A53,ZSSD!D:D,1,0) -> 2825022 | AH53: =VLOOKUP(B53,[2]GRADE!$A:$P,16,0) -> GOLD | AI53: =IF(AH53="SILVER",6.5,IF(AH53="GOLD",8,IF(AH53="INDUSTRIAL",6,IF(AH53="GREEN",7,IF(AH53="BRONZE",5.5,0))))) -> 8
A54: 2825030 | B54: 2825 | C54: 30 | D54: CAR | E54: SERVO HYPERSPORT F5-4 X 2.8 L | F54: =VLOOKUP(C54,'PACK MASTER'!$A$2:$I$512998,9,0)*1000 -> 11.2 | G54: =VLOOKUP(C54,'PACK MASTER'!$A$2:$G$512998,7,0) -> 2.8 | H54: =F54/G54 -> 4 | I54: =VLOOKUP($A54,ZMRP!$C$2:$F$99995,4,0) -> 2450 | J54: =I54/G54 -> 875 | K54: =VLOOKUP($A54,ZLAM!$C$2:$F$99999,4,0) -> 73.5 | L54: =I54*K54/100 -> 1800.75 | M54: =L54/G54 -> 643.125 | N54: =L54/1.18 -> 1526.0593 | O54: =N54/G54 -> 545.02119 | P54: =IFERROR(ABS(VLOOKUP($A54,ZTRV!$D$2:$G$99407,4,0)),0) -> 0 | Q54: =IFERROR(ABS(VLOOKUP($A54,ZTR1!$D$2:$G$99999,4,0)),0) -> 0 | R54: =IFERROR(ABS(VLOOKUP($A54,ZTR2!$D$2:$G$99939,4,0)),0) -> 0 | S54: =SUM(P54:R54)*G54 -> 0 | T54: =N54-S54 -> 1526.0593 | U54: =T54*1.18 -> 1800.75 | V54: =U54/G54 -> 643.125 | W54: =V54*F54 -> 7203 | X54: =I54-U54 -> 649.25 | Y54: =X54*H54 -> 2597 | Z54: =J54-V54 -> 231.875 | AA54: =IFERROR(ABS(VLOOKUP(A54,ZSSD!$D$2:$G$99933,4,0)),AI54) -> 8 | AB54: =IFERROR(IF(VLOOKUP(A54,ZSSD!$D:$H,5,0)="L29",AA54*G54,AA54*L54/100),AA54*L54/100) -> 144.06 | AC54: 2 | AD54: =2*(T54-AB54)/100 -> 27.639986 | AE54: =+AB54/G54 -> 51.45 | AF54: =+AD54/G54 -> 9.8714237 | AG54: =VLOOKUP(A54,ZSSD!D:D,1,0) -> #N/A | AH54: =VLOOKUP(B54,[2]GRADE!$A:$P,16,0) -> GOLD | AI54: =IF(AH54="SILVER",6.5,IF(AH54="GOLD",8,IF(AH54="INDUSTRIAL",6,IF(AH54="GREEN",7,IF(AH54="BRONZE",5.5,0))))) -> 8
A55: 2825185 | B55: =VALUE(LEFT(A55,4)) -> 2825 | C55: =VALUE(RIGHT(A55,3)) -> 185 | D55: =VLOOKUP(C55,Sheet1!$A$2:$K$369991,11,0) -> CAR | E55: SERVO HYPERSPORT F5-10 X 1 L | F55: =VLOOKUP(C55,'PACK MASTER'!$A$2:$I$512998,9,0)*1000 -> 10 | G55: =VLOOKUP(C55,'PACK MASTER'!$A$2:$G$512998,7,0) -> 1 | H55: =F55/G55 -> 10 | I55: =VLOOKUP($A55,ZMRP!$C$2:$F$99995,4,0) -> 880 | J55: =I55/G55 -> 880 | K55: =VLOOKUP($A55,ZLAM!$C$2:$F$99999,4,0) -> 73.5 | L55: =I55*K55/100 -> 646.8 | M55: =L55/G55 -> 646.8 | N55: =L55/1.18 -> 548.13559 | O55: =N55/G55 -> 548.13559 | P55: =IFERROR(ABS(VLOOKUP($A55,ZTRV!$D$2:$G$99407,4,0)),0) -> 140 | Q55: =IFERROR(ABS(VLOOKUP($A55,ZTR1!$D$2:$G$99999,4,0)),0) -> 200 | R55: =IFERROR(ABS(VLOOKUP($A55,ZTR2!$D$2:$G$99939,4,0)),0) -> 0 | S55: =SUM(P55:R55)*G55 -> 340 | T55: =N55-S55 -> 208.13559 | U55: =T55*1.18 -> 245.6 | V55: =U55/G55 -> 245.6 | W55: =V55*F55 -> 2456 | X55: =I55-U55 -> 634.4 | Y55: =X55*H55 -> 6344 | Z55: =J55-V55 -> 634.4 | AA55: =IFERROR(ABS(VLOOKUP(A55,ZSSD!$D$2:$G$99933,4,0)),AI55) -> 8 | AB55: =IFERROR(IF(VLOOKUP(A55,ZSSD!$D:$H,5,0)="L29",AA55*G55,AA55*L55/100),AA55*L55/100) -> 51.744 | AC55: 2 | AD55: =2*(T55-AB55)/100 -> 3.1278319 | AE55: =+AB55/G55 -> 51.744 | AF55: =+AD55/G55 -> 3.1278319 | AG55: =VLOOKUP(A55,ZSSD!D:D,1,0) -> 2825185 | AH55: =VLOOKUP(B55,[2]GRADE!$A:$P,16,0) -> GOLD | AI55: =IF(AH55="SILVER",6.5,IF(AH55="GOLD",8,IF(AH55="INDUSTRIAL",6,IF(AH55="GREEN",7,IF(AH55="BRONZE",5.5,0))))) -> 8
A56: 2825195 | B56: 2825 | C56: 195 | D56: =VLOOKUP(C56,Sheet1!$A$2:$K$369991,11,0) -> CAR | E56: SERVO HYPERSPORT F5-4 X 2.5 L | F56: =VLOOKUP(C56,'PACK MASTER'!$A$2:$I$512998,9,0)*1000 -> 10 | G56: =VLOOKUP(C56,'PACK MASTER'!$A$2:$G$512998,7,0) -> 2.5 | H56: =F56/G56 -> 4 | I56: =VLOOKUP($A56,ZMRP!$C$2:$F$99995,4,0) -> 2190 | J56: =I56/G56 -> 876 | K56: =VLOOKUP($A56,ZLAM!$C$2:$F$99999,4,0) -> 73.5 | L56: =I56*K56/100 -> 1609.65 | M56: =L56/G56 -> 643.86 | N56: =L56/1.18 -> 1364.1102 | O56: =N56/G56 -> 545.64407 | P56: =IFERROR(ABS(VLOOKUP($A56,ZTRV!$D$2:$G$99407,4,0)),0) -> 0 | Q56: =IFERROR(ABS(VLOOKUP($A56,ZTR1!$D$2:$G$99999,4,0)),0) -> 0 | R56: =IFERROR(ABS(VLOOKUP($A56,ZTR2!$D$2:$G$99939,4,0)),0) -> 0 | S56: =SUM(P56:R56)*G56 -> 0 | T56: =N56-S56 -> 1364.1102 | U56: =T56*1.18 -> 1609.65 | V56: =U56/G56 -> 643.86 | W56: =V56*F56 -> 6438.6 | X56: =I56-U56 -> 580.35 | Y56: =X56*H56 -> 2321.4 | Z56: =J56-V56 -> 232.14 | AA56: =IFERROR(ABS(VLOOKUP(A56,ZSSD!$D$2:$G$99933,4,0)),AI56) -> 8 | AB56: =IFERROR(IF(VLOOKUP(A56,ZSSD!$D:$H,5,0)="L29",AA56*G56,AA56*L56/100),AA56*L56/100) -> 128.772 | AC56: 2 | AD56: =2*(T56-AB56)/100 -> 24.706763 | AE56: =+AB56/G56 -> 51.5088 | AF56: =+AD56/G56 -> 9.8827054 | AG56: =VLOOKUP(A56,ZSSD!D:D,1,0) -> #N/A | AH56: =VLOOKUP(B56,[2]GRADE!$A:$P,16,0) -> GOLD | AI56: =IF(AH56="SILVER",6.5,IF(AH56="GOLD",8,IF(AH56="INDUSTRIAL",6,IF(AH56="GREEN",7,IF(AH56="BRONZE",5.5,0))))) -> 8
A57: 2825258 | B57: =VALUE(LEFT(A57,4)) -> 2825 | C57: =VALUE(RIGHT(A57,3)) -> 258 | D57: =VLOOKUP(C57,Sheet1!$A$2:$K$369991,11,0) -> CAR | E57: SERVO HYPERSPORT F5-10 X 1 L PROMO | F57: =VLOOKUP(C57,'PACK MASTER'!$A$2:$I$512998,9,0)*1000 -> 10 | G57: =VLOOKUP(C57,'PACK MASTER'!$A$2:$G$512998,7,0) -> 1 | H57: =F57/G57 -> 10 | I57: =VLOOKUP($A57,ZMRP!$C$2:$F$99995,4,0) -> 880 | J57: =I57/G57 -> 880 | K57: =VLOOKUP($A57,ZLAM!$C$2:$F$99999,4,0) -> 73.5 | L57: =I57*K57/100 -> 646.8 | M57: =L57/G57 -> 646.8 | N57: =L57/1.18 -> 548.13559 | O57: =N57/G57 -> 548.13559 | P57: =IFERROR(ABS(VLOOKUP($A57,ZTRV!$D$2:$G$99407,4,0)),0) -> 40 | Q57: =IFERROR(ABS(VLOOKUP($A57,ZTR1!$D$2:$G$99999,4,0)),0) -> 200 | R57: =IFERROR(ABS(VLOOKUP($A57,ZTR2!$D$2:$G$99939,4,0)),0) -> 0 | S57: =SUM(P57:R57)*G57 -> 240 | T57: =N57-S57 -> 308.13559 | U57: =T57*1.18 -> 363.6 | V57: =U57/G57 -> 363.6 | W57: =V57*F57 -> 3636 | X57: =I57-U57 -> 516.4 | Y57: =X57*H57 -> 5164 | Z57: =J57-V57 -> 516.4 | AA57: =IFERROR(ABS(VLOOKUP(A57,ZSSD!$D$2:$G$99933,4,0)),AI57) -> 8 | AB57: =IFERROR(IF(VLOOKUP(A57,ZSSD!$D:$H,5,0)="L29",AA57*G57,AA57*L57/100),AA57*L57/100) -> 51.744 | AC57: 2 | AD57: =2*(T57-AB57)/100 -> 5.1278319 | AE57: =+AB57/G57 -> 51.744 | AF57: =+AD57/G57 -> 5.1278319 | AG57: =VLOOKUP(A57,ZSSD!D:D,1,0) -> 2825258 | AH57: =VLOOKUP(B57,[2]GRADE!$A:$P,16,0) -> GOLD | AI57: =IF(AH57="SILVER",6.5,IF(AH57="GOLD",8,IF(AH57="INDUSTRIAL",6,IF(AH57="GREEN",7,IF(AH57="BRONZE",5.5,0))))) -> 8
A58: 2828152 | B58: 2828 | C58: =VALUE(RIGHT(A58,3)) -> 152 | D58: CAR | E58: SERVO 4T XTRA-20 X 0.9 L | F58: =VLOOKUP(C58,'PACK MASTER'!$A$2:$I$512998,9,0)*1000 -> 18 | G58: =VLOOKUP(C58,'PACK MASTER'!$A$2:$G$512998,7,0) -> 0.9 | H58: =F58/G58 -> 20 | I58: =VLOOKUP($A58,ZMRP!$C$2:$F$99995,4,0) -> 422 | J58: =I58/G58 -> 468.88889 | K58: =VLOOKUP($A58,ZLAM!$C$2:$F$99999,4,0) -> 74.42 | L58: =I58*K58/100 -> 314.0524 | M58: =L58/G58 -> 348.94711 | N58: =L58/1.18 -> 266.1461 | O58: =N58/G58 -> 295.71789 | P58: =IFERROR(ABS(VLOOKUP($A58,ZTRV!$D$2:$G$99407,4,0)),0) -> 48 | Q58: =IFERROR(ABS(VLOOKUP($A58,ZTR1!$D$2:$G$99999,4,0)),0) -> 0 | R58: =IFERROR(ABS(VLOOKUP($A58,ZTR2!$D$2:$G$99939,4,0)),0) -> 0 | S58: =SUM(P58:R58)*G58 -> 43.2 | T58: =N58-S58 -> 222.9461 | U58: =T58*1.18 -> 263.0764 | V58: =U58/G58 -> 292.30711 | W58: =V58*F58 -> 5261.528 | X58: =I58-U58 -> 158.9236 | Y58: =X58*H58 -> 3178.472 | Z58: =J58-V58 -> 176.58178 | AA58: =IFERROR(ABS(VLOOKUP(A58,ZSSD!$D$2:$G$99933,4,0)),AI58) -> 8 | AB58: =IFERROR(IF(VLOOKUP(A58,ZSSD!$D:$H,5,0)="L29",AA58*G58,AA58*L58/100),AA58*L58/100) -> 25.124192 | AC58: 2 | AD58: =2*(T58-AB58)/100 -> 3.9564382 | AE58: =+AB58/G58 -> 27.915769 | AF58: =+AD58/G58 -> 4.3960424 | AG58: =VLOOKUP(A58,ZSSD!D:D,1,0) -> 2828152 | AH58: =VLOOKUP(B58,[2]GRADE!$A:$P,16,0) -> GOLD | AI58: =IF(AH58="SILVER",6.5,IF(AH58="GOLD",8,IF(AH58="INDUSTRIAL",6,IF(AH58="GREEN",7,IF(AH58="BRONZE",5.5,0))))) -> 8
A59: 2828181 | B59: =VALUE(LEFT(A59,4)) -> 2828 | C59: =VALUE(RIGHT(A59,3)) -> 181 | D59: =VLOOKUP(C59,Sheet1!$A$2:$K$369991,11,0) -> CAN | E59: SERVO 4T XTRA-1 L PROMO | F59: =VLOOKUP(C59,'PACK MASTER'!$A$2:$I$512998,9,0)*1000 -> 1 | G59: =VLOOKUP(C59,'PACK MASTER'!$A$2:$G$512998,7,0) -> 1 | H59: =F59/G59 -> 1 | I59: =VLOOKUP($A59,ZMRP!$C$2:$F$99995,4,0) -> 464 | J59: =I59/G59 -> 464 | K59: =VLOOKUP($A59,ZLAM!$C$2:$F$99999,4,0) -> 74.47 | L59: =I59*K59/100 -> 345.5408 | M59: =L59/G59 -> 345.5408 | N59: =L59/1.18 -> 292.83119 | O59: =N59/G59 -> 292.83119 | P59: =IFERROR(ABS(VLOOKUP($A59,ZTRV!$D$2:$G$99407,4,0)),0) -> 43 | Q59: =IFERROR(ABS(VLOOKUP($A59,ZTR1!$D$2:$G$99999,4,0)),0) -> 0 | R59: =IFERROR(ABS(VLOOKUP($A59,ZTR2!$D$2:$G$99939,4,0)),0) -> 0 | S59: =SUM(P59:R59)*G59 -> 43 | T59: =N59-S59 -> 249.83119 | U59: =T59*1.18 -> 294.8008 | V59: =U59/G59 -> 294.8008 | W59: =V59*F59 -> 294.8008 | X59: =I59-U59 -> 169.1992 | Y59: =X59*H59 -> 169.1992 | Z59: =J59-V59 -> 169.1992 | AA59: =IFERROR(ABS(VLOOKUP(A59,ZSSD!$D$2:$G$99933,4,0)),AI59) -> 8 | AB59: =IFERROR(IF(VLOOKUP(A59,ZSSD!$D:$H,5,0)="L29",AA59*G59,AA59*L59/100),AA59*L59/100) -> 27.643264 | AC59: 2 | AD59: =2*(T59-AB59)/100 -> 4.4437584 | AE59: =+AB59/G59 -> 27.643264 | AF59: =+AD59/G59 -> 4.4437584 | AG59: =VLOOKUP(A59,ZSSD!D:D,1,0) -> 2828181 | AH59: =VLOOKUP(B59,[2]GRADE!$A:$P,16,0) -> GOLD | AI59: =IF(AH59="SILVER",6.5,IF(AH59="GOLD",8,IF(AH59="INDUSTRIAL",6,IF(AH59="GREEN",7,IF(AH59="BRONZE",5.5,0))))) -> 8
A60: 2828184 | B60: 2828 | C60: =VALUE(RIGHT(A60,3)) -> 184 | D60: =VLOOKUP(C60,Sheet1!$A$2:$K$369991,11,0) -> CAR | E60: SERVO 4T XTRA-20 X 1 L | F60: =VLOOKUP(C60,'PACK MASTER'!$A$2:$I$512998,9,0)*1000 -> 20 | G60: =VLOOKUP(C60,'PACK MASTER'!$A$2:$G$512998,7,0) -> 1 | H60: =F60/G60 -> 20 | I60: =VLOOKUP($A60,ZMRP!$C$2:$F$99995,4,0) -> 464 | J60: =I60/G60 -> 464 | K60: =VLOOKUP($A60,ZLAM!$C$2:$F$99999,4,0) -> 74.47 | L60: =I60*K60/100 -> 345.5408 | M60: =L60/G60 -> 345.5408 | N60: =L60/1.18 -> 292.83119 | O60: =N60/G60 -> 292.83119 | P60: =IFERROR(ABS(VLOOKUP($A60,ZTRV!$D$2:$G$99407,4,0)),0) -> 48 | Q60: =IFERROR(ABS(VLOOKUP($A60,ZTR1!$D$2:$G$99999,4,0)),0) -> 0 | R60: =IFERROR(ABS(VLOOKUP($A60,ZTR2!$D$2:$G$99939,4,0)),0) -> 0 | S60: =SUM(P60:R60)*G60 -> 48 | T60: =N60-S60 -> 244.83119 | U60: =T60*1.18 -> 288.9008 | V60: =U60/G60 -> 288.9008 | W60: =V60*F60 -> 5778.016 | X60: =I60-U60 -> 175.0992 | Y60: =X60*H60 -> 3501.984 | Z60: =J60-V60 -> 175.0992 | AA60: =IFERROR(ABS(VLOOKUP(A60,ZSSD!$D$2:$G$99933,4,0)),AI60) -> 8 | AB60: =IFERROR(IF(VLOOKUP(A60,ZSSD!$D:$H,5,0)="L29",AA60*G60,AA60*L60/100),AA60*L60/100) -> 27.643264 | AC60: 2 | AD60: =2*(T60-AB60)/100 -> 4.3437584 | AE60: =+AB60/G60 -> 27.643264 | AF60: =+AD60/G60 -> 4.3437584 | AG60: =VLOOKUP(A60,ZSSD!D:D,1,0) -> 2828184 | AH60: =VLOOKUP(B60,[2]GRADE!$A:$P,16,0) -> GOLD | AI60: =IF(AH60="SILVER",6.5,IF(AH60="GOLD",8,IF(AH60="INDUSTRIAL",6,IF(AH60="GREEN",7,IF(AH60="BRONZE",5.5,0))))) -> 8
A61: 2828229 | B61: =VALUE(LEFT(A61,4)) -> 2828 | C61: =VALUE(RIGHT(A61,3)) -> 229 | D61: =VLOOKUP(C61,Sheet1!$A$2:$K$369991,11,0) -> CAR | E61: SERVO 4T XTRA-20 X 1 L PROMO | F61: =VLOOKUP(C61,'PACK MASTER'!$A$2:$I$512998,9,0)*1000 -> 20 | G61: =VLOOKUP(C61,'PACK MASTER'!$A$2:$G$512998,7,0) -> 1 | H61: =F61/G61 -> 20 | I61: =VLOOKUP($A61,ZMRP!$C$2:$F$99995,4,0) -> 464 | J61: =I61/G61 -> 464 | K61: =VLOOKUP($A61,ZLAM!$C$2:$F$99999,4,0) -> 74.47 | L61: =I61*K61/100 -> 345.5408 | M61: =L61/G61 -> 345.5408 | N61: =L61/1.18 -> 292.83119 | O61: =N61/G61 -> 292.83119 | P61: =IFERROR(ABS(VLOOKUP($A61,ZTRV!$D$2:$G$99407,4,0)),0) -> 43 | Q61: =IFERROR(ABS(VLOOKUP($A61,ZTR1!$D$2:$G$99999,4,0)),0) -> 0 | R61: =IFERROR(ABS(VLOOKUP($A61,ZTR2!$D$2:$G$99939,4,0)),0) -> 0 | S61: =SUM(P61:R61)*G61 -> 43 | T61: =N61-S61 -> 249.83119 | U61: =T61*1.18 -> 294.8008 | V61: =U61/G61 -> 294.8008 | W61: =V61*F61 -> 5896.016 | X61: =I61-U61 -> 169.1992 | Y61: =X61*H61 -> 3383.984 | Z61: =J61-V61 -> 169.1992 | AA61: =IFERROR(ABS(VLOOKUP(A61,ZSSD!$D$2:$G$99933,4,0)),AI61) -> 8 | AB61: =IFERROR(IF(VLOOKUP(A61,ZSSD!$D:$H,5,0)="L29",AA61*G61,AA61*L61/100),AA61*L61/100) -> 27.643264 | AC61: 2 | AD61: =2*(T61-AB61)/100 -> 4.4437584 | AE61: =+AB61/G61 -> 27.643264 | AF61: =+AD61/G61 -> 4.4437584 | AG61: =VLOOKUP(A61,ZSSD!D:D,1,0) -> 2828229 | AH61: =VLOOKUP(B61,[2]GRADE!$A:$P,16,0) -> GOLD | AI61: =IF(AH61="SILVER",6.5,IF(AH61="GOLD",8,IF(AH61="INDUSTRIAL",6,IF(AH61="GREEN",7,IF(AH61="BRONZE",5.5,0))))) -> 8
A62: 2828230 | B62: =VALUE(LEFT(A62,4)) -> 2828 | C62: =VALUE(RIGHT(A62,3)) -> 230 | D62: =VLOOKUP(C62,Sheet1!$A$2:$K$369991,11,0) -> CAR | E62: SERVO 4T XTRA-20 X 0.9 L PROMO | F62: =VLOOKUP(C62,'PACK MASTER'!$A$2:$I$512998,9,0)*1000 -> 18 | G62: =VLOOKUP(C62,'PACK MASTER'!$A$2:$G$512998,7,0) -> 0.9 | H62: =F62/G62 -> 20 | I62: =VLOOKUP($A62,ZMRP!$C$2:$F$99995,4,0) -> 422 | J62: =I62/G62 -> 468.88889 | K62: =VLOOKUP($A62,ZLAM!$C$2:$F$99999,4,0) -> 74.42 | L62: =I62*K62/100 -> 314.0524 | M62: =L62/G62 -> 348.94711 | N62: =L62/1.18 -> 266.1461 | O62: =N62/G62 -> 295.71789 | P62: =IFERROR(ABS(VLOOKUP($A62,ZTRV!$D$2:$G$99407,4,0)),0) -> 43 | Q62: =IFERROR(ABS(VLOOKUP($A62,ZTR1!$D$2:$G$99999,4,0)),0) -> 0 | R62: =IFERROR(ABS(VLOOKUP($A62,ZTR2!$D$2:$G$99939,4,0)),0) -> 0 | S62: =SUM(P62:R62)*G62 -> 38.7 | T62: =N62-S62 -> 227.4461 | U62: =T62*1.18 -> 268.3864 | V62: =U62/G62 -> 298.20711 | W62: =V62*F62 -> 5367.728 | X62: =I62-U62 -> 153.6136 | Y62: =X62*H62 -> 3072.272 | Z62: =J62-V62 -> 170.68178 | AA62: =IFERROR(ABS(VLOOKUP(A62,ZSSD!$D$2:$G$99933,4,0)),AI62) -> 8 | AB62: =IFERROR(IF(VLOOKUP(A62,ZSSD!$D:$H,5,0)="L29",AA62*G62,AA62*L62/100),AA62*L62/100) -> 25.124192 | AC62: 2 | AD62: =2*(T62-AB62)/100 -> 4.0464382 | AE62: =+AB62/G62 -> 27.915769 | AF62: =+AD62/G62 -> 4.4960424 | AG62: =VLOOKUP(A62,ZSSD!D:D,1,0) -> 2828230 | AH62: =VLOOKUP(B62,[2]GRADE!$A:$P,16,0) -> GOLD | AI62: =IF(AH62="SILVER",6.5,IF(AH62="GOLD",8,IF(AH62="INDUSTRIAL",6,IF(AH62="GREEN",7,IF(AH62="BRONZE",5.5,0))))) -> 8
A63: 2829152 | B63: =VALUE(LEFT(A63,4)) -> 2829 | C63: =VALUE(RIGHT(A63,3)) -> 152 | D63: =VLOOKUP(C63,Sheet1!$A$2:$K$369991,11,0) -> CAR | E63: SERVO 4T XTRA 10W-30-20 X 0.9 L | F63: =VLOOKUP(C63,'PACK MASTER'!$A$2:$I$512998,9,0)*1000 -> 18 | G63: =VLOOKUP(C63,'PACK MASTER'!$A$2:$G$512998,7,0) -> 0.9 | H63: =F63/G63 -> 20 | I63: =VLOOKUP($A63,ZMRP!$C$2:$F$99995,4,0) -> 422 | J63: =I63/G63 -> 468.88889 | K63: =VLOOKUP($A63,ZLAM!$C$2:$F$99999,4,0) -> 74.42 | L63: =I63*K63/100 -> 314.0524 | M63: =L63/G63 -> 348.94711 | N63: =L63/1.18 -> 266.1461 | O63: =N63/G63 -> 295.71789 | P63: =IFERROR(ABS(VLOOKUP($A63,ZTRV!$D$2:$G$99407,4,0)),0) -> 48 | Q63: =IFERROR(ABS(VLOOKUP($A63,ZTR1!$D$2:$G$99999,4,0)),0) -> 0 | R63: =IFERROR(ABS(VLOOKUP($A63,ZTR2!$D$2:$G$99939,4,0)),0) -> 0 | S63: =SUM(P63:R63)*G63 -> 43.2 | T63: =N63-S63 -> 222.9461 | U63: =T63*1.18 -> 263.0764 | V63: =U63/G63 -> 292.30711 | W63: =V63*F63 -> 5261.528 | X63: =I63-U63 -> 158.9236 | Y63: =X63*H63 -> 3178.472 | Z63: =J63-V63 -> 176.58178 | AA63: =IFERROR(ABS(VLOOKUP(A63,ZSSD!$D$2:$G$99933,4,0)),AI63) -> 8 | AB63: =IFERROR(IF(VLOOKUP(A63,ZSSD!$D:$H,5,0)="L29",AA63*G63,AA63*L63/100),AA63*L63/100) -> 25.124192 | AC63: 2 | AD63: =2*(T63-AB63)/100 -> 3.9564382 | AE63: =+AB63/G63 -> 27.915769 | AF63: =+AD63/G63 -> 4.3960424 | AG63: =VLOOKUP(A63,ZSSD!D:D,1,0) -> 2829152 | AH63: =VLOOKUP(B63,[2]GRADE!$A:$P,16,0) -> GOLD | AI63: =IF(AH63="SILVER",6.5,IF(AH63="GOLD",8,IF(AH63="INDUSTRIAL",6,IF(AH63="GREEN",7,IF(AH63="BRONZE",5.5,0))))) -> 8
A64: 2829184 | B64: =VALUE(LEFT(A64,4)) -> 2829 | C64: =VALUE(RIGHT(A64,3)) -> 184 | D64: =VLOOKUP(C64,Sheet1!$A$2:$K$369991,11,0) -> CAR | E64: SERVO 4T XTRA 10W-30-20 X 1 L | F64: =VLOOKUP(C64,'PACK MASTER'!$A$2:$I$512998,9,0)*1000 -> 20 | G64: =VLOOKUP(C64,'PACK MASTER'!$A$2:$G$512998,7,0) -> 1 | H64: =F64/G64 -> 20 | I64: =VLOOKUP($A64,ZMRP!$C$2:$F$99995,4,0) -> 464 | J64: =I64/G64 -> 464 | K64: =VLOOKUP($A64,ZLAM!$C$2:$F$99999,4,0) -> 74.47 | L64: =I64*K64/100 -> 345.5408 | M64: =L64/G64 -> 345.5408 | N64: =L64/1.18 -> 292.83119 | O64: =N64/G64 -> 292.83119 | P64: =IFERROR(ABS(VLOOKUP($A64,ZTRV!$D$2:$G$99407,4,0)),0) -> 48 | Q64: =IFERROR(ABS(VLOOKUP($A64,ZTR1!$D$2:$G$99999,4,0)),0) -> 0 | R64: =IFERROR(ABS(VLOOKUP($A64,ZTR2!$D$2:$G$99939,4,0)),0) -> 0 | S64: =SUM(P64:R64)*G64 -> 48 | T64: =N64-S64 -> 244.83119 | U64: =T64*1.18 -> 288.9008 | V64: =U64/G64 -> 288.9008 | W64: =V64*F64 -> 5778.016 | X64: =I64-U64 -> 175.0992 | Y64: =X64*H64 -> 3501.984 | Z64: =J64-V64 -> 175.0992 | AA64: =IFERROR(ABS(VLOOKUP(A64,ZSSD!$D$2:$G$99933,4,0)),AI64) -> 8 | AB64: =IFERROR(IF(VLOOKUP(A64,ZSSD!$D:$H,5,0)="L29",AA64*G64,AA64*L64/100),AA64*L64/100) -> 27.643264 | AC64: 2 | AD64: =2*(T64-AB64)/100 -> 4.3437584 | AE64: =+AB64/G64 -> 27.643264 | AF64: =+AD64/G64 -> 4.3437584 | AG64: =VLOOKUP(A64,ZSSD!D:D,1,0) -> 2829184 | AH64: =VLOOKUP(B64,[2]GRADE!$A:$P,16,0) -> GOLD | AI64: =IF(AH64="SILVER",6.5,IF(AH64="GOLD",8,IF(AH64="INDUSTRIAL",6,IF(AH64="GREEN",7,IF(AH64="BRONZE",5.5,0))))) -> 8
A65: 2829229 | B65: =VALUE(LEFT(A65,4)) -> 2829 | C65: =VALUE(RIGHT(A65,3)) -> 229 | D65: =VLOOKUP(C65,Sheet1!$A$2:$K$369991,11,0) -> CAR | E65: SERVO 4T XTRA 10W-30-20 X 1 L PROMO | F65: =VLOOKUP(C65,'PACK MASTER'!$A$2:$I$512998,9,0)*1000 -> 20 | G65: =VLOOKUP(C65,'PACK MASTER'!$A$2:$G$512998,7,0) -> 1 | H65: =F65/G65 -> 20 | I65: =VLOOKUP($A65,ZMRP!$C$2:$F$99995,4,0) -> 464 | J65: =I65/G65 -> 464 | K65: =VLOOKUP($A65,ZLAM!$C$2:$F$99999,4,0) -> 74.47 | L65: =I65*K65/100 -> 345.5408 | M65: =L65/G65 -> 345.5408 | N65: =L65/1.18 -> 292.83119 | O65: =N65/G65 -> 292.83119 | P65: =IFERROR(ABS(VLOOKUP($A65,ZTRV!$D$2:$G$99407,4,0)),0) -> 43 | Q65: =IFERROR(ABS(VLOOKUP($A65,ZTR1!$D$2:$G$99999,4,0)),0) -> 0 | R65: =IFERROR(ABS(VLOOKUP($A65,ZTR2!$D$2:$G$99939,4,0)),0) -> 0 | S65: =SUM(P65:R65)*G65 -> 43 | T65: =N65-S65 -> 249.83119 | U65: =T65*1.18 -> 294.8008 | V65: =U65/G65 -> 294.8008 | W65: =V65*F65 -> 5896.016 | X65: =I65-U65 -> 169.1992 | Y65: =X65*H65 -> 3383.984 | Z65: =J65-V65 -> 169.1992 | AA65: =IFERROR(ABS(VLOOKUP(A65,ZSSD!$D$2:$G$99933,4,0)),AI65) -> 8 | AB65: =IFERROR(IF(VLOOKUP(A65,ZSSD!$D:$H,5,0)="L29",AA65*G65,AA65*L65/100),AA65*L65/100) -> 27.643264 | AC65: 2 | AD65: =2*(T65-AB65)/100 -> 4.4437584 | AE65: =+AB65/G65 -> 27.643264 | AF65: =+AD65/G65 -> 4.4437584 | AG65: =VLOOKUP(A65,ZSSD!D:D,1,0) -> 2829229 | AH65: =VLOOKUP(B65,[2]GRADE!$A:$P,16,0) -> GOLD | AI65: =IF(AH65="SILVER",6.5,IF(AH65="GOLD",8,IF(AH65="INDUSTRIAL",6,IF(AH65="GREEN",7,IF(AH65="BRONZE",5.5,0))))) -> 8
A66: 2829230 | B66: =VALUE(LEFT(A66,4)) -> 2829 | C66: =VALUE(RIGHT(A66,3)) -> 230 | D66: =VLOOKUP(C66,Sheet1!$A$2:$K$369991,11,0) -> CAR | E66: SERVO 4T XTRA 10W-30-20 X 0.9 L PROMO | F66: =VLOOKUP(C66,'PACK MASTER'!$A$2:$I$512998,9,0)*1000 -> 18 | G66: =VLOOKUP(C66,'PACK MASTER'!$A$2:$G$512998,7,0) -> 0.9 | H66: =F66/G66 -> 20 | I66: =VLOOKUP($A66,ZMRP!$C$2:$F$99995,4,0) -> 422 | J66: =I66/G66 -> 468.88889 | K66: =VLOOKUP($A66,ZLAM!$C$2:$F$99999,4,0) -> 74.42 | L66: =I66*K66/100 -> 314.0524 | M66: =L66/G66 -> 348.94711 | N66: =L66/1.18 -> 266.1461 | O66: =N66/G66 -> 295.71789 | P66: =IFERROR(ABS(VLOOKUP($A66,ZTRV!$D$2:$G$99407,4,0)),0) -> 43 | Q66: =IFERROR(ABS(VLOOKUP($A66,ZTR1!$D$2:$G$99999,4,0)),0) -> 0 | R66: =IFERROR(ABS(VLOOKUP($A66,ZTR2!$D$2:$G$99939,4,0)),0) -> 0 | S66: =SUM(P66:R66)*G66 -> 38.7 | T66: =N66-S66 -> 227.4461 | U66: =T66*1.18 -> 268.3864 | V66: =U66/G66 -> 298.20711 | W66: =V66*F66 -> 5367.728 | X66: =I66-U66 -> 153.6136 | Y66: =X66*H66 -> 3072.272 | Z66: =J66-V66 -> 170.68178 | AA66: =IFERROR(ABS(VLOOKUP(A66,ZSSD!$D$2:$G$99933,4,0)),AI66) -> 8 | AB66: =IFERROR(IF(VLOOKUP(A66,ZSSD!$D:$H,5,0)="L29",AA66*G66,AA66*L66/100),AA66*L66/100) -> 25.124192 | AC66: 2 | AD66: =2*(T66-AB66)/100 -> 4.0464382 | AE66: =+AB66/G66 -> 27.915769 | AF66: =+AD66/G66 -> 4.4960424 | AG66: =VLOOKUP(A66,ZSSD!D:D,1,0) -> 2829230 | AH66: =VLOOKUP(B66,[2]GRADE!$A:$P,16,0) -> GOLD | AI66: =IF(AH66="SILVER",6.5,IF(AH66="GOLD",8,IF(AH66="INDUSTRIAL",6,IF(AH66="GREEN",7,IF(AH66="BRONZE",5.5,0))))) -> 8
A67: 2830229 | B67: =VALUE(LEFT(A67,4)) -> 2830 | C67: =VALUE(RIGHT(A67,3)) -> 229 | D67: =VLOOKUP(C67,Sheet1!$A$2:$K$369991,11,0) -> CAR | E67: SERVO 4T XTRA 20W-50-20 X 1 L PROMO | F67: =VLOOKUP(C67,'PACK MASTER'!$A$2:$I$512998,9,0)*1000 -> 20 | G67: =VLOOKUP(C67,'PACK MASTER'!$A$2:$G$512998,7,0) -> 1 | H67: =F67/G67 -> 20 | I67: =VLOOKUP($A67,ZMRP!$C$2:$F$99995,4,0) -> 464 | J67: =I67/G67 -> 464 | K67: =VLOOKUP($A67,ZLAM!$C$2:$F$99999,4,0) -> 74.47 | L67: =I67*K67/100 -> 345.5408 | M67: =L67/G67 -> 345.5408 | N67: =L67/1.18 -> 292.83119 | O67: =N67/G67 -> 292.83119 | P67: =IFERROR(ABS(VLOOKUP($A67,ZTRV!$D$2:$G$99407,4,0)),0) -> 43 | Q67: =IFERROR(ABS(VLOOKUP($A67,ZTR1!$D$2:$G$99999,4,0)),0) -> 0 | R67: =IFERROR(ABS(VLOOKUP($A67,ZTR2!$D$2:$G$99939,4,0)),0) -> 0 | S67: =SUM(P67:R67)*G67 -> 43 | T67: =N67-S67 -> 249.83119 | U67: =T67*1.18 -> 294.8008 | V67: =U67/G67 -> 294.8008 | W67: =V67*F67 -> 5896.016 | X67: =I67-U67 -> 169.1992 | Y67: =X67*H67 -> 3383.984 | Z67: =J67-V67 -> 169.1992 | AA67: =IFERROR(ABS(VLOOKUP(A67,ZSSD!$D$2:$G$99933,4,0)),AI67) -> 8 | AB67: =IFERROR(IF(VLOOKUP(A67,ZSSD!$D:$H,5,0)="L29",AA67*G67,AA67*L67/100),AA67*L67/100) -> 27.643264 | AC67: 2 | AD67: =2*(T67-AB67)/100 -> 4.4437584 | AE67: =+AB67/G67 -> 27.643264 | AF67: =+AD67/G67 -> 4.4437584 | AG67: =VLOOKUP(A67,ZSSD!D:D,1,0) -> 2830229 | AH67: =VLOOKUP(B67,[2]GRADE!$A:$P,16,0) -> GOLD | AI67: =IF(AH67="SILVER",6.5,IF(AH67="GOLD",8,IF(AH67="INDUSTRIAL",6,IF(AH67="GREEN",7,IF(AH67="BRONZE",5.5,0))))) -> 8
A68: 2830230 | B68: =VALUE(LEFT(A68,4)) -> 2830 | C68: =VALUE(RIGHT(A68,3)) -> 230 | D68: =VLOOKUP(C68,Sheet1!$A$2:$K$369991,11,0) -> CAR | E68: SERVO 4T XTRA 20W-50-20 X 0.9 L PROMO | F68: =VLOOKUP(C68,'PACK MASTER'!$A$2:$I$512998,9,0)*1000 -> 18 | G68: =VLOOKUP(C68,'PACK MASTER'!$A$2:$G$512998,7,0) -> 0.9 | H68: =F68/G68 -> 20 | I68: =VLOOKUP($A68,ZMRP!$C$2:$F$99995,4,0) -> 422 | J68: =I68/G68 -> 468.88889 | K68: =VLOOKUP($A68,ZLAM!$C$2:$F$99999,4,0) -> 74.42 | L68: =I68*K68/100 -> 314.0524 | M68: =L68/G68 -> 348.94711 | N68: =L68/1.18 -> 266.1461 | O68: =N68/G68 -> 295.71789 | P68: =IFERROR(ABS(VLOOKUP($A68,ZTRV!$D$2:$G$99407,4,0)),0) -> 43 | Q68: =IFERROR(ABS(VLOOKUP($A68,ZTR1!$D$2:$G$99999,4,0)),0) -> 0 | R68: =IFERROR(ABS(VLOOKUP($A68,ZTR2!$D$2:$G$99939,4,0)),0) -> 0 | S68: =SUM(P68:R68)*G68 -> 38.7 | T68: =N68-S68 -> 227.4461 | U68: =T68*1.18 -> 268.3864 | V68: =U68/G68 -> 298.20711 | W68: =V68*F68 -> 5367.728 | X68: =I68-U68 -> 153.6136 | Y68: =X68*H68 -> 3072.272 | Z68: =J68-V68 -> 170.68178 | AA68: =IFERROR(ABS(VLOOKUP(A68,ZSSD!$D$2:$G$99933,4,0)),AI68) -> 8 | AB68: =IFERROR(IF(VLOOKUP(A68,ZSSD!$D:$H,5,0)="L29",AA68*G68,AA68*L68/100),AA68*L68/100) -> 25.124192 | AC68: 2 | AD68: =2*(T68-AB68)/100 -> 4.0464382 | AE68: =+AB68/G68 -> 27.915769 | AF68: =+AD68/G68 -> 4.4960424 | AG68: =VLOOKUP(A68,ZSSD!D:D,1,0) -> 2830230 | AH68: =VLOOKUP(B68,[2]GRADE!$A:$P,16,0) -> GOLD | AI68: =IF(AH68="SILVER",6.5,IF(AH68="GOLD",8,IF(AH68="INDUSTRIAL",6,IF(AH68="GREEN",7,IF(AH68="BRONZE",5.5,0))))) -> 8
A69: 2844024 | B69: =VALUE(LEFT(A69,4)) -> 2844 | C69: =VALUE(RIGHT(A69,3)) -> 24 | D69: =VLOOKUP(C69,Sheet1!$A$2:$K$369991,11,0) -> CAR | E69: HERO XOTIC+ 10W30-10 X 1.2 L | F69: =VLOOKUP(C69,'PACK MASTER'!$A$2:$I$512998,9,0)*1000 -> 12 | G69: =VLOOKUP(C69,'PACK MASTER'!$A$2:$G$512998,7,0) -> 1.2 | H69: =F69/G69 -> 10 | I69: =VLOOKUP($A69,ZMRP!$C$2:$F$99995,4,0) -> 1150 | J69: =I69/G69 -> 958.33333 | K69: =VLOOKUP($A69,ZLAM!$C$2:$F$99999,4,0) -> 50.28 | L69: =I69*K69/100 -> 578.22 | M69: =L69/G69 -> 481.85 | N69: =L69/1.18 -> 490.01695 | O69: =N69/G69 -> 408.34746 | P69: =IFERROR(ABS(VLOOKUP($A69,ZTRV!$D$2:$G$99407,4,0)),0) -> 0 | Q69: =IFERROR(ABS(VLOOKUP($A69,ZTR1!$D$2:$G$99999,4,0)),0) -> 0 | R69: =IFERROR(ABS(VLOOKUP($A69,ZTR2!$D$2:$G$99939,4,0)),0) -> 0 | S69: =SUM(P69:R69)*G69 -> 0 | T69: =N69-S69 -> 490.01695 | U69: =T69*1.18 -> 578.22 | V69: =U69/G69 -> 481.85 | W69: =V69*F69 -> 5782.2 | X69: =I69-U69 -> 571.78 | Y69: =X69*H69 -> 5717.8 | Z69: =J69-V69 -> 476.48333 | AA69: =IFERROR(ABS(VLOOKUP(A69,ZSSD!$D$2:$G$99933,4,0)),AI69) -> 6.5 | AB69: =IFERROR(IF(VLOOKUP(A69,ZSSD!$D:$H,5,0)="L29",AA69*G69,AA69*L69/100),AA69*L69/100) -> 37.5843 | AC69: 2 | AD69: =2*(T69-AB69)/100 -> 9.048653 | AE69: =+AB69/G69 -> 31.32025 | AF69: =+AD69/G69 -> 7.5405442 | AG69: =VLOOKUP(A69,ZSSD!D:D,1,0) -> #N/A | AH69: =VLOOKUP(B69,[2]GRADE!$A:$P,16,0) -> SILVER | AI69: =IF(AH69="SILVER",6.5,IF(AH69="GOLD",8,IF(AH69="INDUSTRIAL",6,IF(AH69="GREEN",7,IF(AH69="BRONZE",5.5,0))))) -> 6.5
